[06/Aug/2017 22:07:58] "GET / HTTP/1.1" 200 1716
[06/Aug/2017 22:08:02] "GET / HTTP/1.1" 200 1716
Not Found: /ops
[06/Aug/2017 22:08:07] "GET /ops HTTP/1.1" 404 1940
Not Found: /users
[06/Aug/2017 22:08:36] "GET /users HTTP/1.1" 404 1946
Performing system checks...

System check identified no issues (0 silenced).
August 06, 2017 - 22:07:54
Django version 1.11.3, using settings 'api.settings'
Starting development server at http://0:8000/
Quit the server with CONTROL-C.
Unhandled exception in thread started by <function wrapper at 0x7ff7d2937aa0>
Performing system checks...

Traceback (most recent call last):
  File "/home/ochlo/py/tutorial/env/local/lib/python2.7/site-packages/django/utils/autoreload.py", line 227, in wrapper
    fn(*args, **kwargs)
  File "/home/ochlo/py/tutorial/env/local/lib/python2.7/site-packages/django/core/management/commands/runserver.py", line 125, in inner_run
    self.check(display_num_errors=True)
  File "/home/ochlo/py/tutorial/env/local/lib/python2.7/site-packages/django/core/management/base.py", line 359, in check
    include_deployment_checks=include_deployment_checks,
  File "/home/ochlo/py/tutorial/env/local/lib/python2.7/site-packages/django/core/management/base.py", line 346, in _run_checks
    return checks.run_checks(**kwargs)
  File "/home/ochlo/py/tutorial/env/local/lib/python2.7/site-packages/django/core/checks/registry.py", line 81, in run_checks
    new_errors = check(app_configs=app_configs)
  File "/home/ochlo/py/tutorial/env/local/lib/python2.7/site-packages/django/core/checks/urls.py", line 16, in check_url_config
    return check_resolver(resolver)
  File "/home/ochlo/py/tutorial/env/local/lib/python2.7/site-packages/django/core/checks/urls.py", line 26, in check_resolver
    return check_method()
  File "/home/ochlo/py/tutorial/env/local/lib/python2.7/site-packages/django/urls/resolvers.py", line 254, in check
    for pattern in self.url_patterns:
  File "/home/ochlo/py/tutorial/env/local/lib/python2.7/site-packages/django/utils/functional.py", line 35, in __get__
    res = instance.__dict__[self.name] = self.func(instance)
  File "/home/ochlo/py/tutorial/env/local/lib/python2.7/site-packages/django/urls/resolvers.py", line 405, in url_patterns
    patterns = getattr(self.urlconf_module, "urlpatterns", self.urlconf_module)
  File "/home/ochlo/py/tutorial/env/local/lib/python2.7/site-packages/django/utils/functional.py", line 35, in __get__
    res = instance.__dict__[self.name] = self.func(instance)
  File "/home/ochlo/py/tutorial/env/local/lib/python2.7/site-packages/django/urls/resolvers.py", line 398, in urlconf_module
    return import_module(self.urlconf_name)
  File "/usr/lib/python2.7/importlib/__init__.py", line 37, in import_module
    __import__(name)
  File "/home/ochlo/py/api/api/urls.py", line 20, in <module>
    url(r'^ops/', inclue(ops)),
NameError: name 'inclue' is not defined
Unhandled exception in thread started by <function wrapper at 0x7fef79314aa0>
Performing system checks...

Traceback (most recent call last):
  File "/home/ochlo/py/tutorial/env/local/lib/python2.7/site-packages/django/utils/autoreload.py", line 227, in wrapper
    fn(*args, **kwargs)
  File "/home/ochlo/py/tutorial/env/local/lib/python2.7/site-packages/django/core/management/commands/runserver.py", line 125, in inner_run
    self.check(display_num_errors=True)
  File "/home/ochlo/py/tutorial/env/local/lib/python2.7/site-packages/django/core/management/base.py", line 359, in check
    include_deployment_checks=include_deployment_checks,
  File "/home/ochlo/py/tutorial/env/local/lib/python2.7/site-packages/django/core/management/base.py", line 346, in _run_checks
    return checks.run_checks(**kwargs)
  File "/home/ochlo/py/tutorial/env/local/lib/python2.7/site-packages/django/core/checks/registry.py", line 81, in run_checks
    new_errors = check(app_configs=app_configs)
  File "/home/ochlo/py/tutorial/env/local/lib/python2.7/site-packages/django/core/checks/urls.py", line 16, in check_url_config
    return check_resolver(resolver)
  File "/home/ochlo/py/tutorial/env/local/lib/python2.7/site-packages/django/core/checks/urls.py", line 26, in check_resolver
    return check_method()
  File "/home/ochlo/py/tutorial/env/local/lib/python2.7/site-packages/django/urls/resolvers.py", line 254, in check
    for pattern in self.url_patterns:
  File "/home/ochlo/py/tutorial/env/local/lib/python2.7/site-packages/django/utils/functional.py", line 35, in __get__
    res = instance.__dict__[self.name] = self.func(instance)
  File "/home/ochlo/py/tutorial/env/local/lib/python2.7/site-packages/django/urls/resolvers.py", line 405, in url_patterns
    patterns = getattr(self.urlconf_module, "urlpatterns", self.urlconf_module)
  File "/home/ochlo/py/tutorial/env/local/lib/python2.7/site-packages/django/utils/functional.py", line 35, in __get__
    res = instance.__dict__[self.name] = self.func(instance)
  File "/home/ochlo/py/tutorial/env/local/lib/python2.7/site-packages/django/urls/resolvers.py", line 398, in urlconf_module
    return import_module(self.urlconf_name)
  File "/usr/lib/python2.7/importlib/__init__.py", line 37, in import_module
    __import__(name)
  File "/home/ochlo/py/api/api/urls.py", line 20, in <module>
    url(r'^ops/', include(ops.urls)),
NameError: name 'ops' is not defined
Not Found: /ops
[06/Aug/2017 22:12:27] "GET /ops HTTP/1.1" 404 1940
Not Found: /users
[06/Aug/2017 22:12:32] "GET /users HTTP/1.1" 404 1946
[06/Aug/2017 22:12:38] "GET /admin HTTP/1.1" 301 0
[06/Aug/2017 22:12:38] "GET /admin/ HTTP/1.1" 302 0
[06/Aug/2017 22:12:38] "GET /admin/login/?next=/admin/ HTTP/1.1" 200 1650
[06/Aug/2017 22:12:38] "GET /static/admin/css/login.css HTTP/1.1" 200 1203
[06/Aug/2017 22:12:38] "GET /static/admin/css/base.css HTTP/1.1" 200 16066
[06/Aug/2017 22:12:38] "GET /static/admin/css/fonts.css HTTP/1.1" 200 423
[06/Aug/2017 22:12:38] "GET /static/admin/fonts/Roboto-Regular-webfont.woff HTTP/1.1" 200 80304
[06/Aug/2017 22:12:38] "GET /static/admin/fonts/Roboto-Light-webfont.woff HTTP/1.1" 200 81348
[06/Aug/2017 22:12:48] "POST /admin/login/?next=/admin/ HTTP/1.1" 302 0
[06/Aug/2017 22:12:48] "GET /admin/ HTTP/1.1" 200 2779
[06/Aug/2017 22:12:48] "GET /static/admin/css/dashboard.css HTTP/1.1" 200 412
[06/Aug/2017 22:12:48] "GET /static/admin/fonts/Roboto-Bold-webfont.woff HTTP/1.1" 200 82564
[06/Aug/2017 22:12:48] "GET /static/admin/img/icon-changelink.svg HTTP/1.1" 200 380
[06/Aug/2017 22:12:48] "GET /static/admin/img/icon-addlink.svg HTTP/1.1" 200 331
[06/Aug/2017 22:12:51] "GET /admin/auth/user/ HTTP/1.1" 200 6449
[06/Aug/2017 22:12:51] "GET /static/admin/css/changelists.css HTTP/1.1" 200 6170
[06/Aug/2017 22:12:51] "GET /static/admin/js/core.js HTTP/1.1" 200 7976
[06/Aug/2017 22:12:51] "GET /static/admin/js/jquery.init.js HTTP/1.1" 200 363
[06/Aug/2017 22:12:51] "GET /static/admin/js/vendor/jquery/jquery.js HTTP/1.1" 200 258648
[06/Aug/2017 22:12:51] "GET /admin/jsi18n/ HTTP/1.1" 200 3217
[06/Aug/2017 22:12:51] "GET /static/admin/js/admin/RelatedObjectLookups.js HTTP/1.1" 200 6591
[06/Aug/2017 22:12:51] "GET /static/admin/js/actions.js HTTP/1.1" 200 6501
[06/Aug/2017 22:12:51] "GET /static/admin/js/urlify.js HTTP/1.1" 200 8186
[06/Aug/2017 22:12:51] "GET /static/admin/js/prepopulate.js HTTP/1.1" 200 1538
[06/Aug/2017 22:12:51] "GET /static/admin/js/vendor/xregexp/xregexp.js HTTP/1.1" 200 128820
[06/Aug/2017 22:12:51] "GET /static/admin/img/search.svg HTTP/1.1" 200 458
[06/Aug/2017 22:12:51] "GET /static/admin/img/icon-yes.svg HTTP/1.1" 200 436
[06/Aug/2017 22:12:51] "GET /static/admin/img/tooltag-add.svg HTTP/1.1" 200 331
[06/Aug/2017 22:12:51] "GET /static/admin/img/sorting-icons.svg HTTP/1.1" 200 1097
[06/Aug/2017 22:12:54] "GET /admin/auth/user/1/change/ HTTP/1.1" 200 13400
[06/Aug/2017 22:12:54] "GET /static/admin/css/forms.css HTTP/1.1" 200 8173
[06/Aug/2017 22:12:54] "GET /admin/jsi18n/ HTTP/1.1" 200 3217
[06/Aug/2017 22:12:54] "GET /static/admin/js/SelectBox.js HTTP/1.1" 200 5755
[06/Aug/2017 22:12:54] "GET /static/admin/js/SelectFilter2.js HTTP/1.1" 200 12389
[06/Aug/2017 22:12:54] "GET /static/admin/js/calendar.js HTTP/1.1" 200 7790
[06/Aug/2017 22:12:54] "GET /static/admin/js/admin/DateTimeShortcuts.js HTTP/1.1" 200 20529
[06/Aug/2017 22:12:54] "GET /static/admin/js/change_form.js HTTP/1.1" 200 712
[06/Aug/2017 22:12:54] "GET /static/admin/js/prepopulate_init.js HTTP/1.1" 200 495
[06/Aug/2017 22:12:54] "GET /static/admin/css/widgets.css HTTP/1.1" 200 10340
[06/Aug/2017 22:12:54] "GET /static/admin/img/icon-unknown.svg HTTP/1.1" 200 655
[06/Aug/2017 22:12:54] "GET /static/admin/img/selector-icons.svg HTTP/1.1" 200 3291
[06/Aug/2017 22:12:54] "GET /static/admin/img/icon-unknown-alt.svg HTTP/1.1" 200 655
[06/Aug/2017 22:12:54] "GET /static/admin/img/icon-clock.svg HTTP/1.1" 200 677
[06/Aug/2017 22:12:54] "GET /static/admin/img/icon-calendar.svg HTTP/1.1" 200 1086
[06/Aug/2017 22:13:02] "GET /admin/password_change/ HTTP/1.1" 200 2588
[06/Aug/2017 22:13:12] "POST /admin/password_change/ HTTP/1.1" 200 2724
[06/Aug/2017 22:13:57] "GET /admin/ HTTP/1.1" 200 2779
Performing system checks...

System check identified no issues (0 silenced).
August 06, 2017 - 22:12:24
Django version 1.11.3, using settings 'api.settings'
Starting development server at http://0:8000/
Quit the server with CONTROL-C.
Unhandled exception in thread started by <function wrapper at 0x7fde878d3aa0>
Performing system checks...

Traceback (most recent call last):
  File "/home/ochlo/py/tutorial/env/local/lib/python2.7/site-packages/django/utils/autoreload.py", line 227, in wrapper
    fn(*args, **kwargs)
  File "/home/ochlo/py/tutorial/env/local/lib/python2.7/site-packages/django/core/management/commands/runserver.py", line 125, in inner_run
    self.check(display_num_errors=True)
  File "/home/ochlo/py/tutorial/env/local/lib/python2.7/site-packages/django/core/management/base.py", line 359, in check
    include_deployment_checks=include_deployment_checks,
  File "/home/ochlo/py/tutorial/env/local/lib/python2.7/site-packages/django/core/management/base.py", line 346, in _run_checks
    return checks.run_checks(**kwargs)
  File "/home/ochlo/py/tutorial/env/local/lib/python2.7/site-packages/django/core/checks/registry.py", line 81, in run_checks
    new_errors = check(app_configs=app_configs)
  File "/home/ochlo/py/tutorial/env/local/lib/python2.7/site-packages/django/core/checks/urls.py", line 16, in check_url_config
    return check_resolver(resolver)
  File "/home/ochlo/py/tutorial/env/local/lib/python2.7/site-packages/django/core/checks/urls.py", line 26, in check_resolver
    return check_method()
  File "/home/ochlo/py/tutorial/env/local/lib/python2.7/site-packages/django/urls/resolvers.py", line 254, in check
    for pattern in self.url_patterns:
  File "/home/ochlo/py/tutorial/env/local/lib/python2.7/site-packages/django/utils/functional.py", line 35, in __get__
    res = instance.__dict__[self.name] = self.func(instance)
  File "/home/ochlo/py/tutorial/env/local/lib/python2.7/site-packages/django/urls/resolvers.py", line 405, in url_patterns
    patterns = getattr(self.urlconf_module, "urlpatterns", self.urlconf_module)
  File "/home/ochlo/py/tutorial/env/local/lib/python2.7/site-packages/django/utils/functional.py", line 35, in __get__
    res = instance.__dict__[self.name] = self.func(instance)
  File "/home/ochlo/py/tutorial/env/local/lib/python2.7/site-packages/django/urls/resolvers.py", line 398, in urlconf_module
    return import_module(self.urlconf_name)
  File "/usr/lib/python2.7/importlib/__init__.py", line 37, in import_module
    __import__(name)
  File "/home/ochlo/py/api/api/urls.py", line 19, in <module>
    from api.ops import views
ImportError: No module named ops
Unhandled exception in thread started by <function wrapper at 0x7f5e74a60aa0>
Performing system checks...

Traceback (most recent call last):
  File "/home/ochlo/py/tutorial/env/local/lib/python2.7/site-packages/django/utils/autoreload.py", line 227, in wrapper
    fn(*args, **kwargs)
  File "/home/ochlo/py/tutorial/env/local/lib/python2.7/site-packages/django/core/management/commands/runserver.py", line 125, in inner_run
    self.check(display_num_errors=True)
  File "/home/ochlo/py/tutorial/env/local/lib/python2.7/site-packages/django/core/management/base.py", line 359, in check
    include_deployment_checks=include_deployment_checks,
  File "/home/ochlo/py/tutorial/env/local/lib/python2.7/site-packages/django/core/management/base.py", line 346, in _run_checks
    return checks.run_checks(**kwargs)
  File "/home/ochlo/py/tutorial/env/local/lib/python2.7/site-packages/django/core/checks/registry.py", line 81, in run_checks
    new_errors = check(app_configs=app_configs)
  File "/home/ochlo/py/tutorial/env/local/lib/python2.7/site-packages/django/core/checks/urls.py", line 16, in check_url_config
    return check_resolver(resolver)
  File "/home/ochlo/py/tutorial/env/local/lib/python2.7/site-packages/django/core/checks/urls.py", line 26, in check_resolver
    return check_method()
  File "/home/ochlo/py/tutorial/env/local/lib/python2.7/site-packages/django/urls/resolvers.py", line 254, in check
    for pattern in self.url_patterns:
  File "/home/ochlo/py/tutorial/env/local/lib/python2.7/site-packages/django/utils/functional.py", line 35, in __get__
    res = instance.__dict__[self.name] = self.func(instance)
  File "/home/ochlo/py/tutorial/env/local/lib/python2.7/site-packages/django/urls/resolvers.py", line 405, in url_patterns
    patterns = getattr(self.urlconf_module, "urlpatterns", self.urlconf_module)
  File "/home/ochlo/py/tutorial/env/local/lib/python2.7/site-packages/django/utils/functional.py", line 35, in __get__
    res = instance.__dict__[self.name] = self.func(instance)
  File "/home/ochlo/py/tutorial/env/local/lib/python2.7/site-packages/django/urls/resolvers.py", line 398, in urlconf_module
    return import_module(self.urlconf_name)
  File "/usr/lib/python2.7/importlib/__init__.py", line 37, in import_module
    __import__(name)
  File "/home/ochlo/py/api/api/urls.py", line 19, in <module>
    from api.ops import views
ImportError: No module named ops
Unhandled exception in thread started by <function wrapper at 0x7fac64e09aa0>
Performing system checks...

Traceback (most recent call last):
  File "/home/ochlo/py/tutorial/env/local/lib/python2.7/site-packages/django/utils/autoreload.py", line 227, in wrapper
    fn(*args, **kwargs)
  File "/home/ochlo/py/tutorial/env/local/lib/python2.7/site-packages/django/core/management/commands/runserver.py", line 125, in inner_run
    self.check(display_num_errors=True)
  File "/home/ochlo/py/tutorial/env/local/lib/python2.7/site-packages/django/core/management/base.py", line 359, in check
    include_deployment_checks=include_deployment_checks,
  File "/home/ochlo/py/tutorial/env/local/lib/python2.7/site-packages/django/core/management/base.py", line 346, in _run_checks
    return checks.run_checks(**kwargs)
  File "/home/ochlo/py/tutorial/env/local/lib/python2.7/site-packages/django/core/checks/registry.py", line 81, in run_checks
    new_errors = check(app_configs=app_configs)
  File "/home/ochlo/py/tutorial/env/local/lib/python2.7/site-packages/django/core/checks/urls.py", line 16, in check_url_config
    return check_resolver(resolver)
  File "/home/ochlo/py/tutorial/env/local/lib/python2.7/site-packages/django/core/checks/urls.py", line 26, in check_resolver
    return check_method()
  File "/home/ochlo/py/tutorial/env/local/lib/python2.7/site-packages/django/urls/resolvers.py", line 254, in check
    for pattern in self.url_patterns:
  File "/home/ochlo/py/tutorial/env/local/lib/python2.7/site-packages/django/utils/functional.py", line 35, in __get__
    res = instance.__dict__[self.name] = self.func(instance)
  File "/home/ochlo/py/tutorial/env/local/lib/python2.7/site-packages/django/urls/resolvers.py", line 405, in url_patterns
    patterns = getattr(self.urlconf_module, "urlpatterns", self.urlconf_module)
  File "/home/ochlo/py/tutorial/env/local/lib/python2.7/site-packages/django/utils/functional.py", line 35, in __get__
    res = instance.__dict__[self.name] = self.func(instance)
  File "/home/ochlo/py/tutorial/env/local/lib/python2.7/site-packages/django/urls/resolvers.py", line 398, in urlconf_module
    return import_module(self.urlconf_name)
  File "/usr/lib/python2.7/importlib/__init__.py", line 37, in import_module
    __import__(name)
  File "/home/ochlo/py/api/api/urls.py", line 19, in <module>
    from api.ops import views
ImportError: No module named ops
Unhandled exception in thread started by <function wrapper at 0x7f1bfdfc8aa0>
Performing system checks...

Traceback (most recent call last):
  File "/home/ochlo/py/tutorial/env/local/lib/python2.7/site-packages/django/utils/autoreload.py", line 227, in wrapper
    fn(*args, **kwargs)
  File "/home/ochlo/py/tutorial/env/local/lib/python2.7/site-packages/django/core/management/commands/runserver.py", line 125, in inner_run
    self.check(display_num_errors=True)
  File "/home/ochlo/py/tutorial/env/local/lib/python2.7/site-packages/django/core/management/base.py", line 359, in check
    include_deployment_checks=include_deployment_checks,
  File "/home/ochlo/py/tutorial/env/local/lib/python2.7/site-packages/django/core/management/base.py", line 346, in _run_checks
    return checks.run_checks(**kwargs)
  File "/home/ochlo/py/tutorial/env/local/lib/python2.7/site-packages/django/core/checks/registry.py", line 81, in run_checks
    new_errors = check(app_configs=app_configs)
  File "/home/ochlo/py/tutorial/env/local/lib/python2.7/site-packages/django/core/checks/urls.py", line 16, in check_url_config
    return check_resolver(resolver)
  File "/home/ochlo/py/tutorial/env/local/lib/python2.7/site-packages/django/core/checks/urls.py", line 26, in check_resolver
    return check_method()
  File "/home/ochlo/py/tutorial/env/local/lib/python2.7/site-packages/django/urls/resolvers.py", line 254, in check
    for pattern in self.url_patterns:
  File "/home/ochlo/py/tutorial/env/local/lib/python2.7/site-packages/django/utils/functional.py", line 35, in __get__
    res = instance.__dict__[self.name] = self.func(instance)
  File "/home/ochlo/py/tutorial/env/local/lib/python2.7/site-packages/django/urls/resolvers.py", line 405, in url_patterns
    patterns = getattr(self.urlconf_module, "urlpatterns", self.urlconf_module)
  File "/home/ochlo/py/tutorial/env/local/lib/python2.7/site-packages/django/utils/functional.py", line 35, in __get__
    res = instance.__dict__[self.name] = self.func(instance)
  File "/home/ochlo/py/tutorial/env/local/lib/python2.7/site-packages/django/urls/resolvers.py", line 398, in urlconf_module
    return import_module(self.urlconf_name)
  File "/usr/lib/python2.7/importlib/__init__.py", line 37, in import_module
    __import__(name)
  File "/home/ochlo/py/api/api/urls.py", line 19, in <module>
    from api.ops import views
ImportError: No module named ops
Unhandled exception in thread started by <function wrapper at 0x7f08e6772aa0>
Performing system checks...

Traceback (most recent call last):
  File "/home/ochlo/py/tutorial/env/local/lib/python2.7/site-packages/django/utils/autoreload.py", line 227, in wrapper
    fn(*args, **kwargs)
  File "/home/ochlo/py/tutorial/env/local/lib/python2.7/site-packages/django/core/management/commands/runserver.py", line 125, in inner_run
    self.check(display_num_errors=True)
  File "/home/ochlo/py/tutorial/env/local/lib/python2.7/site-packages/django/core/management/base.py", line 359, in check
    include_deployment_checks=include_deployment_checks,
  File "/home/ochlo/py/tutorial/env/local/lib/python2.7/site-packages/django/core/management/base.py", line 346, in _run_checks
    return checks.run_checks(**kwargs)
  File "/home/ochlo/py/tutorial/env/local/lib/python2.7/site-packages/django/core/checks/registry.py", line 81, in run_checks
    new_errors = check(app_configs=app_configs)
  File "/home/ochlo/py/tutorial/env/local/lib/python2.7/site-packages/django/core/checks/urls.py", line 16, in check_url_config
    return check_resolver(resolver)
  File "/home/ochlo/py/tutorial/env/local/lib/python2.7/site-packages/django/core/checks/urls.py", line 26, in check_resolver
    return check_method()
  File "/home/ochlo/py/tutorial/env/local/lib/python2.7/site-packages/django/urls/resolvers.py", line 254, in check
    for pattern in self.url_patterns:
  File "/home/ochlo/py/tutorial/env/local/lib/python2.7/site-packages/django/utils/functional.py", line 35, in __get__
    res = instance.__dict__[self.name] = self.func(instance)
  File "/home/ochlo/py/tutorial/env/local/lib/python2.7/site-packages/django/urls/resolvers.py", line 405, in url_patterns
    patterns = getattr(self.urlconf_module, "urlpatterns", self.urlconf_module)
  File "/home/ochlo/py/tutorial/env/local/lib/python2.7/site-packages/django/utils/functional.py", line 35, in __get__
    res = instance.__dict__[self.name] = self.func(instance)
  File "/home/ochlo/py/tutorial/env/local/lib/python2.7/site-packages/django/urls/resolvers.py", line 398, in urlconf_module
    return import_module(self.urlconf_name)
  File "/usr/lib/python2.7/importlib/__init__.py", line 37, in import_module
    __import__(name)
  File "/home/ochlo/py/api/api/urls.py", line 19, in <module>
    from api.ops import views
ImportError: No module named ops
[06/Aug/2017 23:11:52] "GET /users HTTP/1.1" 301 0
[06/Aug/2017 23:11:52] "GET /users/ HTTP/1.1" 200 9707
[06/Aug/2017 23:11:52] "GET /static/rest_framework/js/ajax-form.js HTTP/1.1" 200 2876
[06/Aug/2017 23:11:52] "GET /static/rest_framework/js/jquery-1.12.4.min.js HTTP/1.1" 200 97163
[06/Aug/2017 23:11:52] "GET /static/rest_framework/js/csrf.js HTTP/1.1" 200 1735
[06/Aug/2017 23:11:52] "GET /static/rest_framework/js/default.js HTTP/1.1" 200 1262
[06/Aug/2017 23:11:52] "GET /static/rest_framework/js/bootstrap.min.js HTTP/1.1" 200 37045
[06/Aug/2017 23:11:52] "GET /static/rest_framework/js/prettify-min.js HTTP/1.1" 200 13632
[06/Aug/2017 23:11:52] "GET /static/rest_framework/img/grid.png HTTP/1.1" 200 1458
Not Found: /ops
[06/Aug/2017 23:11:58] "GET /ops HTTP/1.1" 404 4027
[06/Aug/2017 23:12:06] "GET /groups HTTP/1.1" 301 0
/home/ochlo/py/tutorial/env/local/lib/python2.7/site-packages/rest_framework/pagination.py:208: UnorderedObjectListWarning: Pagination may yield inconsistent results with an unordered object_list: <class 'django.contrib.auth.models.Group'> QuerySet.
  paginator = self.django_paginator_class(queryset, page_size)
[06/Aug/2017 23:12:06] "GET /groups/ HTTP/1.1" 200 8541
[06/Aug/2017 23:12:31] "GET /groups/?format=api HTTP/1.1" 200 8618
[06/Aug/2017 23:12:43] "POST /groups/?format=api HTTP/1.1" 201 8889
[06/Aug/2017 23:12:49] "OPTIONS /groups/?format=api HTTP/1.1" 200 9517
[06/Aug/2017 23:13:03] "GET /?format=api HTTP/1.1" 200 5428
[06/Aug/2017 23:13:08] "GET /users/?format=api HTTP/1.1" 200 9860
[06/Aug/2017 23:13:33] "POST /users/?format=api HTTP/1.1" 201 10105
[06/Aug/2017 23:13:43] "GET /?format=api HTTP/1.1" 200 5428
Performing system checks...

System check identified no issues (0 silenced).
August 09, 2017 - 06:53:08
Django version 1.11.3, using settings 'api.settings'
Starting development server at http://0:8000/
Quit the server with CONTROL-C.
Performing system checks...

System check identified no issues (0 silenced).
August 09, 2017 - 06:56:25
Django version 1.11.3, using settings 'api.settings'
Starting development server at http://0:8000/
Quit the server with CONTROL-C.
Unhandled exception in thread started by <function wrapper at 0x7f747008b848>
Performing system checks...

Traceback (most recent call last):
  File "/home/ochlo/py/env/local/lib/python2.7/site-packages/django/utils/autoreload.py", line 227, in wrapper
    fn(*args, **kwargs)
  File "/home/ochlo/py/env/local/lib/python2.7/site-packages/django/core/management/commands/runserver.py", line 125, in inner_run
    self.check(display_num_errors=True)
  File "/home/ochlo/py/env/local/lib/python2.7/site-packages/django/core/management/base.py", line 359, in check
    include_deployment_checks=include_deployment_checks,
  File "/home/ochlo/py/env/local/lib/python2.7/site-packages/django/core/management/base.py", line 346, in _run_checks
    return checks.run_checks(**kwargs)
  File "/home/ochlo/py/env/local/lib/python2.7/site-packages/django/core/checks/registry.py", line 81, in run_checks
    new_errors = check(app_configs=app_configs)
  File "/home/ochlo/py/env/local/lib/python2.7/site-packages/django/core/checks/urls.py", line 16, in check_url_config
    return check_resolver(resolver)
  File "/home/ochlo/py/env/local/lib/python2.7/site-packages/django/core/checks/urls.py", line 26, in check_resolver
    return check_method()
  File "/home/ochlo/py/env/local/lib/python2.7/site-packages/django/urls/resolvers.py", line 254, in check
    for pattern in self.url_patterns:
  File "/home/ochlo/py/env/local/lib/python2.7/site-packages/django/utils/functional.py", line 35, in __get__
    res = instance.__dict__[self.name] = self.func(instance)
  File "/home/ochlo/py/env/local/lib/python2.7/site-packages/django/urls/resolvers.py", line 405, in url_patterns
    patterns = getattr(self.urlconf_module, "urlpatterns", self.urlconf_module)
  File "/home/ochlo/py/env/local/lib/python2.7/site-packages/django/utils/functional.py", line 35, in __get__
    res = instance.__dict__[self.name] = self.func(instance)
  File "/home/ochlo/py/env/local/lib/python2.7/site-packages/django/urls/resolvers.py", line 398, in urlconf_module
    return import_module(self.urlconf_name)
  File "/usr/lib/python2.7/importlib/__init__.py", line 37, in import_module
    __import__(name)
  File "/home/ochlo/py/api/api/urls.py", line 19, in <module>
    from ops import views
  File "/home/ochlo/py/api/ops/views.py", line 9, in <module>
    from ops.serializers import UserSerializer, GroupSerializer
  File "/home/ochlo/py/api/ops/serializers.py", line 25
    instance.cmdprotocol = validated_data.get('cmdprotocol' instance.cmdprotocol)
                                                                   ^
SyntaxError: invalid syntax
Unhandled exception in thread started by <function wrapper at 0x7f3998bf8848>
Performing system checks...

Traceback (most recent call last):
  File "/home/ochlo/py/env/local/lib/python2.7/site-packages/django/utils/autoreload.py", line 227, in wrapper
    fn(*args, **kwargs)
  File "/home/ochlo/py/env/local/lib/python2.7/site-packages/django/core/management/commands/runserver.py", line 125, in inner_run
    self.check(display_num_errors=True)
  File "/home/ochlo/py/env/local/lib/python2.7/site-packages/django/core/management/base.py", line 359, in check
    include_deployment_checks=include_deployment_checks,
  File "/home/ochlo/py/env/local/lib/python2.7/site-packages/django/core/management/base.py", line 346, in _run_checks
    return checks.run_checks(**kwargs)
  File "/home/ochlo/py/env/local/lib/python2.7/site-packages/django/core/checks/registry.py", line 81, in run_checks
    new_errors = check(app_configs=app_configs)
  File "/home/ochlo/py/env/local/lib/python2.7/site-packages/django/core/checks/urls.py", line 16, in check_url_config
    return check_resolver(resolver)
  File "/home/ochlo/py/env/local/lib/python2.7/site-packages/django/core/checks/urls.py", line 26, in check_resolver
    return check_method()
  File "/home/ochlo/py/env/local/lib/python2.7/site-packages/django/urls/resolvers.py", line 254, in check
    for pattern in self.url_patterns:
  File "/home/ochlo/py/env/local/lib/python2.7/site-packages/django/utils/functional.py", line 35, in __get__
    res = instance.__dict__[self.name] = self.func(instance)
  File "/home/ochlo/py/env/local/lib/python2.7/site-packages/django/urls/resolvers.py", line 405, in url_patterns
    patterns = getattr(self.urlconf_module, "urlpatterns", self.urlconf_module)
  File "/home/ochlo/py/env/local/lib/python2.7/site-packages/django/utils/functional.py", line 35, in __get__
    res = instance.__dict__[self.name] = self.func(instance)
  File "/home/ochlo/py/env/local/lib/python2.7/site-packages/django/urls/resolvers.py", line 398, in urlconf_module
    return import_module(self.urlconf_name)
  File "/usr/lib/python2.7/importlib/__init__.py", line 37, in import_module
    __import__(name)
  File "/home/ochlo/py/api/api/urls.py", line 19, in <module>
    from ops import views
  File "/home/ochlo/py/api/ops/views.py", line 9, in <module>
    from ops.serializers import UserSerializer, GroupSerializer
  File "/home/ochlo/py/api/ops/serializers.py", line 25
    instance.cmdprotocol = validated_data.get('cmdprotocol' instance.cmdprotocol)
                                                                   ^
SyntaxError: invalid syntax
Unhandled exception in thread started by <function wrapper at 0x7f34d7403848>
Performing system checks...

Traceback (most recent call last):
  File "/home/ochlo/py/env/local/lib/python2.7/site-packages/django/utils/autoreload.py", line 227, in wrapper
    fn(*args, **kwargs)
  File "/home/ochlo/py/env/local/lib/python2.7/site-packages/django/core/management/commands/runserver.py", line 125, in inner_run
    self.check(display_num_errors=True)
  File "/home/ochlo/py/env/local/lib/python2.7/site-packages/django/core/management/base.py", line 359, in check
    include_deployment_checks=include_deployment_checks,
  File "/home/ochlo/py/env/local/lib/python2.7/site-packages/django/core/management/base.py", line 346, in _run_checks
    return checks.run_checks(**kwargs)
  File "/home/ochlo/py/env/local/lib/python2.7/site-packages/django/core/checks/registry.py", line 81, in run_checks
    new_errors = check(app_configs=app_configs)
  File "/home/ochlo/py/env/local/lib/python2.7/site-packages/django/core/checks/urls.py", line 16, in check_url_config
    return check_resolver(resolver)
  File "/home/ochlo/py/env/local/lib/python2.7/site-packages/django/core/checks/urls.py", line 26, in check_resolver
    return check_method()
  File "/home/ochlo/py/env/local/lib/python2.7/site-packages/django/urls/resolvers.py", line 254, in check
    for pattern in self.url_patterns:
  File "/home/ochlo/py/env/local/lib/python2.7/site-packages/django/utils/functional.py", line 35, in __get__
    res = instance.__dict__[self.name] = self.func(instance)
  File "/home/ochlo/py/env/local/lib/python2.7/site-packages/django/urls/resolvers.py", line 405, in url_patterns
    patterns = getattr(self.urlconf_module, "urlpatterns", self.urlconf_module)
  File "/home/ochlo/py/env/local/lib/python2.7/site-packages/django/utils/functional.py", line 35, in __get__
    res = instance.__dict__[self.name] = self.func(instance)
  File "/home/ochlo/py/env/local/lib/python2.7/site-packages/django/urls/resolvers.py", line 398, in urlconf_module
    return import_module(self.urlconf_name)
  File "/usr/lib/python2.7/importlib/__init__.py", line 37, in import_module
    __import__(name)
  File "/home/ochlo/py/api/api/urls.py", line 19, in <module>
    from ops import views
  File "/home/ochlo/py/api/ops/views.py", line 9, in <module>
    from ops.serializers import UserSerializer, GroupSerializer
  File "/home/ochlo/py/api/ops/serializers.py", line 25
    instance.cmdprotocol = validated_data.get('cmdprotocol' instance.cmdprotocol)
                                                                   ^
SyntaxError: invalid syntax
Unhandled exception in thread started by <function wrapper at 0x7f48432a2848>
Performing system checks...

Traceback (most recent call last):
  File "/home/ochlo/py/env/local/lib/python2.7/site-packages/django/utils/autoreload.py", line 227, in wrapper
    fn(*args, **kwargs)
  File "/home/ochlo/py/env/local/lib/python2.7/site-packages/django/core/management/commands/runserver.py", line 125, in inner_run
    self.check(display_num_errors=True)
  File "/home/ochlo/py/env/local/lib/python2.7/site-packages/django/core/management/base.py", line 359, in check
    include_deployment_checks=include_deployment_checks,
  File "/home/ochlo/py/env/local/lib/python2.7/site-packages/django/core/management/base.py", line 346, in _run_checks
    return checks.run_checks(**kwargs)
  File "/home/ochlo/py/env/local/lib/python2.7/site-packages/django/core/checks/registry.py", line 81, in run_checks
    new_errors = check(app_configs=app_configs)
  File "/home/ochlo/py/env/local/lib/python2.7/site-packages/django/core/checks/urls.py", line 16, in check_url_config
    return check_resolver(resolver)
  File "/home/ochlo/py/env/local/lib/python2.7/site-packages/django/core/checks/urls.py", line 26, in check_resolver
    return check_method()
  File "/home/ochlo/py/env/local/lib/python2.7/site-packages/django/urls/resolvers.py", line 254, in check
    for pattern in self.url_patterns:
  File "/home/ochlo/py/env/local/lib/python2.7/site-packages/django/utils/functional.py", line 35, in __get__
    res = instance.__dict__[self.name] = self.func(instance)
  File "/home/ochlo/py/env/local/lib/python2.7/site-packages/django/urls/resolvers.py", line 405, in url_patterns
    patterns = getattr(self.urlconf_module, "urlpatterns", self.urlconf_module)
  File "/home/ochlo/py/env/local/lib/python2.7/site-packages/django/utils/functional.py", line 35, in __get__
    res = instance.__dict__[self.name] = self.func(instance)
  File "/home/ochlo/py/env/local/lib/python2.7/site-packages/django/urls/resolvers.py", line 398, in urlconf_module
    return import_module(self.urlconf_name)
  File "/usr/lib/python2.7/importlib/__init__.py", line 37, in import_module
    __import__(name)
  File "/home/ochlo/py/api/api/urls.py", line 19, in <module>
    from ops import views
  File "/home/ochlo/py/api/ops/views.py", line 9, in <module>
    from ops.serializers import UserSerializer, GroupSerializer
  File "/home/ochlo/py/api/ops/serializers.py", line 25
    instance.cmdprotocol = validated_data.get('cmdprotocol' instance.cmdprotocol)
                                                                   ^
SyntaxError: invalid syntax
Unhandled exception in thread started by <function wrapper at 0x7fc21a26f848>
Performing system checks...

Traceback (most recent call last):
  File "/home/ochlo/py/env/local/lib/python2.7/site-packages/django/utils/autoreload.py", line 227, in wrapper
    fn(*args, **kwargs)
  File "/home/ochlo/py/env/local/lib/python2.7/site-packages/django/core/management/commands/runserver.py", line 125, in inner_run
    self.check(display_num_errors=True)
  File "/home/ochlo/py/env/local/lib/python2.7/site-packages/django/core/management/base.py", line 359, in check
    include_deployment_checks=include_deployment_checks,
  File "/home/ochlo/py/env/local/lib/python2.7/site-packages/django/core/management/base.py", line 346, in _run_checks
    return checks.run_checks(**kwargs)
  File "/home/ochlo/py/env/local/lib/python2.7/site-packages/django/core/checks/registry.py", line 81, in run_checks
    new_errors = check(app_configs=app_configs)
  File "/home/ochlo/py/env/local/lib/python2.7/site-packages/django/core/checks/urls.py", line 16, in check_url_config
    return check_resolver(resolver)
  File "/home/ochlo/py/env/local/lib/python2.7/site-packages/django/core/checks/urls.py", line 26, in check_resolver
    return check_method()
  File "/home/ochlo/py/env/local/lib/python2.7/site-packages/django/urls/resolvers.py", line 254, in check
    for pattern in self.url_patterns:
  File "/home/ochlo/py/env/local/lib/python2.7/site-packages/django/utils/functional.py", line 35, in __get__
    res = instance.__dict__[self.name] = self.func(instance)
  File "/home/ochlo/py/env/local/lib/python2.7/site-packages/django/urls/resolvers.py", line 405, in url_patterns
    patterns = getattr(self.urlconf_module, "urlpatterns", self.urlconf_module)
  File "/home/ochlo/py/env/local/lib/python2.7/site-packages/django/utils/functional.py", line 35, in __get__
    res = instance.__dict__[self.name] = self.func(instance)
  File "/home/ochlo/py/env/local/lib/python2.7/site-packages/django/urls/resolvers.py", line 398, in urlconf_module
    return import_module(self.urlconf_name)
  File "/usr/lib/python2.7/importlib/__init__.py", line 37, in import_module
    __import__(name)
  File "/home/ochlo/py/api/api/urls.py", line 19, in <module>
    from ops import views
  File "/home/ochlo/py/api/ops/views.py", line 9, in <module>
    from ops.serializers import UserSerializer, GroupSerializer
  File "/home/ochlo/py/api/ops/serializers.py", line 3, in <module>
    from ops.models import CmdProtocols, CMDPROTOCOLS_CHOICES
ImportError: cannot import name CMDPROTOCOLS_CHOICES
Unhandled exception in thread started by <function wrapper at 0x7f6164022848>
Performing system checks...

Traceback (most recent call last):
  File "/home/ochlo/py/env/local/lib/python2.7/site-packages/django/utils/autoreload.py", line 227, in wrapper
    fn(*args, **kwargs)
  File "/home/ochlo/py/env/local/lib/python2.7/site-packages/django/core/management/commands/runserver.py", line 125, in inner_run
    self.check(display_num_errors=True)
  File "/home/ochlo/py/env/local/lib/python2.7/site-packages/django/core/management/base.py", line 359, in check
    include_deployment_checks=include_deployment_checks,
  File "/home/ochlo/py/env/local/lib/python2.7/site-packages/django/core/management/base.py", line 346, in _run_checks
    return checks.run_checks(**kwargs)
  File "/home/ochlo/py/env/local/lib/python2.7/site-packages/django/core/checks/registry.py", line 81, in run_checks
    new_errors = check(app_configs=app_configs)
  File "/home/ochlo/py/env/local/lib/python2.7/site-packages/django/core/checks/urls.py", line 16, in check_url_config
    return check_resolver(resolver)
  File "/home/ochlo/py/env/local/lib/python2.7/site-packages/django/core/checks/urls.py", line 26, in check_resolver
    return check_method()
  File "/home/ochlo/py/env/local/lib/python2.7/site-packages/django/urls/resolvers.py", line 254, in check
    for pattern in self.url_patterns:
  File "/home/ochlo/py/env/local/lib/python2.7/site-packages/django/utils/functional.py", line 35, in __get__
    res = instance.__dict__[self.name] = self.func(instance)
  File "/home/ochlo/py/env/local/lib/python2.7/site-packages/django/urls/resolvers.py", line 405, in url_patterns
    patterns = getattr(self.urlconf_module, "urlpatterns", self.urlconf_module)
  File "/home/ochlo/py/env/local/lib/python2.7/site-packages/django/utils/functional.py", line 35, in __get__
    res = instance.__dict__[self.name] = self.func(instance)
  File "/home/ochlo/py/env/local/lib/python2.7/site-packages/django/urls/resolvers.py", line 398, in urlconf_module
    return import_module(self.urlconf_name)
  File "/usr/lib/python2.7/importlib/__init__.py", line 37, in import_module
    __import__(name)
  File "/home/ochlo/py/api/api/urls.py", line 19, in <module>
    from ops import views
  File "/home/ochlo/py/api/ops/views.py", line 9, in <module>
    from ops.serializers import UserSerializer, GroupSerializer
  File "/home/ochlo/py/api/ops/serializers.py", line 16, in <module>
    class CmdProtocolSerializer(serializers.Serializer):
  File "/home/ochlo/py/api/ops/serializers.py", line 18, in CmdProtocolSerializer
    cmdprotocol = serializers.CharField(choices=CMDPROTOCOLS_CHOICES)
NameError: name 'CMDPROTOCOLS_CHOICES' is not defined
Unhandled exception in thread started by <function wrapper at 0x7f16e84a1848>
Performing system checks...

Traceback (most recent call last):
  File "/home/ochlo/py/env/local/lib/python2.7/site-packages/django/utils/autoreload.py", line 227, in wrapper
    fn(*args, **kwargs)
  File "/home/ochlo/py/env/local/lib/python2.7/site-packages/django/core/management/commands/runserver.py", line 125, in inner_run
    self.check(display_num_errors=True)
  File "/home/ochlo/py/env/local/lib/python2.7/site-packages/django/core/management/base.py", line 359, in check
    include_deployment_checks=include_deployment_checks,
  File "/home/ochlo/py/env/local/lib/python2.7/site-packages/django/core/management/base.py", line 346, in _run_checks
    return checks.run_checks(**kwargs)
  File "/home/ochlo/py/env/local/lib/python2.7/site-packages/django/core/checks/registry.py", line 81, in run_checks
    new_errors = check(app_configs=app_configs)
  File "/home/ochlo/py/env/local/lib/python2.7/site-packages/django/core/checks/urls.py", line 16, in check_url_config
    return check_resolver(resolver)
  File "/home/ochlo/py/env/local/lib/python2.7/site-packages/django/core/checks/urls.py", line 26, in check_resolver
    return check_method()
  File "/home/ochlo/py/env/local/lib/python2.7/site-packages/django/urls/resolvers.py", line 254, in check
    for pattern in self.url_patterns:
  File "/home/ochlo/py/env/local/lib/python2.7/site-packages/django/utils/functional.py", line 35, in __get__
    res = instance.__dict__[self.name] = self.func(instance)
  File "/home/ochlo/py/env/local/lib/python2.7/site-packages/django/urls/resolvers.py", line 405, in url_patterns
    patterns = getattr(self.urlconf_module, "urlpatterns", self.urlconf_module)
  File "/home/ochlo/py/env/local/lib/python2.7/site-packages/django/utils/functional.py", line 35, in __get__
    res = instance.__dict__[self.name] = self.func(instance)
  File "/home/ochlo/py/env/local/lib/python2.7/site-packages/django/urls/resolvers.py", line 398, in urlconf_module
    return import_module(self.urlconf_name)
  File "/usr/lib/python2.7/importlib/__init__.py", line 37, in import_module
    __import__(name)
  File "/home/ochlo/py/api/api/urls.py", line 19, in <module>
    from ops import views
  File "/home/ochlo/py/api/ops/views.py", line 9, in <module>
    from ops.serializers import UserSerializer, GroupSerializer
  File "/home/ochlo/py/api/ops/serializers.py", line 3, in <module>
    from ops.models import CmdProtocols, CMDPROTOCOLS_CHOICES
ImportError: cannot import name CMDPROTOCOLS_CHOICES
Unhandled exception in thread started by <function wrapper at 0x7f2e244d5848>
Performing system checks...

Traceback (most recent call last):
  File "/home/ochlo/py/env/local/lib/python2.7/site-packages/django/utils/autoreload.py", line 227, in wrapper
    fn(*args, **kwargs)
  File "/home/ochlo/py/env/local/lib/python2.7/site-packages/django/core/management/commands/runserver.py", line 125, in inner_run
    self.check(display_num_errors=True)
  File "/home/ochlo/py/env/local/lib/python2.7/site-packages/django/core/management/base.py", line 359, in check
    include_deployment_checks=include_deployment_checks,
  File "/home/ochlo/py/env/local/lib/python2.7/site-packages/django/core/management/base.py", line 346, in _run_checks
    return checks.run_checks(**kwargs)
  File "/home/ochlo/py/env/local/lib/python2.7/site-packages/django/core/checks/registry.py", line 81, in run_checks
    new_errors = check(app_configs=app_configs)
  File "/home/ochlo/py/env/local/lib/python2.7/site-packages/django/core/checks/urls.py", line 16, in check_url_config
    return check_resolver(resolver)
  File "/home/ochlo/py/env/local/lib/python2.7/site-packages/django/core/checks/urls.py", line 26, in check_resolver
    return check_method()
  File "/home/ochlo/py/env/local/lib/python2.7/site-packages/django/urls/resolvers.py", line 254, in check
    for pattern in self.url_patterns:
  File "/home/ochlo/py/env/local/lib/python2.7/site-packages/django/utils/functional.py", line 35, in __get__
    res = instance.__dict__[self.name] = self.func(instance)
  File "/home/ochlo/py/env/local/lib/python2.7/site-packages/django/urls/resolvers.py", line 405, in url_patterns
    patterns = getattr(self.urlconf_module, "urlpatterns", self.urlconf_module)
  File "/home/ochlo/py/env/local/lib/python2.7/site-packages/django/utils/functional.py", line 35, in __get__
    res = instance.__dict__[self.name] = self.func(instance)
  File "/home/ochlo/py/env/local/lib/python2.7/site-packages/django/urls/resolvers.py", line 398, in urlconf_module
    return import_module(self.urlconf_name)
  File "/usr/lib/python2.7/importlib/__init__.py", line 37, in import_module
    __import__(name)
  File "/home/ochlo/py/api/api/urls.py", line 19, in <module>
    from ops import views
  File "/home/ochlo/py/api/ops/views.py", line 9, in <module>
    from ops.serializers import UserSerializer, GroupSerializer
  File "/home/ochlo/py/api/ops/serializers.py", line 3, in <module>
    from ops.models import CmdProtocols, CMDPROTOCOLS_CHOICES
ImportError: cannot import name CMDPROTOCOLS_CHOICES
Unhandled exception in thread started by <function wrapper at 0x7f4ad2f91848>
Performing system checks...

Traceback (most recent call last):
  File "/home/ochlo/py/env/local/lib/python2.7/site-packages/django/utils/autoreload.py", line 227, in wrapper
    fn(*args, **kwargs)
  File "/home/ochlo/py/env/local/lib/python2.7/site-packages/django/core/management/commands/runserver.py", line 125, in inner_run
    self.check(display_num_errors=True)
  File "/home/ochlo/py/env/local/lib/python2.7/site-packages/django/core/management/base.py", line 359, in check
    include_deployment_checks=include_deployment_checks,
  File "/home/ochlo/py/env/local/lib/python2.7/site-packages/django/core/management/base.py", line 346, in _run_checks
    return checks.run_checks(**kwargs)
  File "/home/ochlo/py/env/local/lib/python2.7/site-packages/django/core/checks/registry.py", line 81, in run_checks
    new_errors = check(app_configs=app_configs)
  File "/home/ochlo/py/env/local/lib/python2.7/site-packages/django/core/checks/urls.py", line 16, in check_url_config
    return check_resolver(resolver)
  File "/home/ochlo/py/env/local/lib/python2.7/site-packages/django/core/checks/urls.py", line 26, in check_resolver
    return check_method()
  File "/home/ochlo/py/env/local/lib/python2.7/site-packages/django/urls/resolvers.py", line 254, in check
    for pattern in self.url_patterns:
  File "/home/ochlo/py/env/local/lib/python2.7/site-packages/django/utils/functional.py", line 35, in __get__
    res = instance.__dict__[self.name] = self.func(instance)
  File "/home/ochlo/py/env/local/lib/python2.7/site-packages/django/urls/resolvers.py", line 405, in url_patterns
    patterns = getattr(self.urlconf_module, "urlpatterns", self.urlconf_module)
  File "/home/ochlo/py/env/local/lib/python2.7/site-packages/django/utils/functional.py", line 35, in __get__
    res = instance.__dict__[self.name] = self.func(instance)
  File "/home/ochlo/py/env/local/lib/python2.7/site-packages/django/urls/resolvers.py", line 398, in urlconf_module
    return import_module(self.urlconf_name)
  File "/usr/lib/python2.7/importlib/__init__.py", line 37, in import_module
    __import__(name)
  File "/home/ochlo/py/api/api/urls.py", line 19, in <module>
    from ops import views
  File "/home/ochlo/py/api/ops/views.py", line 9, in <module>
    from ops.serializers import UserSerializer, GroupSerializer
  File "/home/ochlo/py/api/ops/serializers.py", line 16, in <module>
    class CmdProtocolSerializer(serializers.Serializer):
  File "/home/ochlo/py/api/ops/serializers.py", line 18, in CmdProtocolSerializer
    cmdprotocol = serializers.CharField(choices=CmdProtocols.CMDPROTOCOLS_CHOICES)
  File "/home/ochlo/py/env/local/lib/python2.7/site-packages/rest_framework/fields.py", line 739, in __init__
    super(CharField, self).__init__(**kwargs)
TypeError: __init__() got an unexpected keyword argument 'choices'
Not Found: /ops/cmd/1/
[10/Aug/2017 00:20:22] "GET /ops/cmd/1/ HTTP/1.1" 404 4786
Not Found: /ops/cmd/2/
[10/Aug/2017 00:20:33] "GET /ops/cmd/2/ HTTP/1.1" 404 4786
Internal Server Error: /ops/cmd/
Traceback (most recent call last):
  File "/media/ubuntu/OSDisk/Users/jason.c.brown/Desktop/git/env/local/lib/python2.7/site-packages/django/core/handlers/exception.py", line 41, in inner
    response = get_response(request)
  File "/media/ubuntu/OSDisk/Users/jason.c.brown/Desktop/git/env/local/lib/python2.7/site-packages/django/core/handlers/base.py", line 187, in _get_response
    response = self.process_exception_by_middleware(e, request)
  File "/media/ubuntu/OSDisk/Users/jason.c.brown/Desktop/git/env/local/lib/python2.7/site-packages/django/core/handlers/base.py", line 185, in _get_response
    response = wrapped_callback(request, *callback_args, **callback_kwargs)
  File "/media/ubuntu/OSDisk/Users/jason.c.brown/Desktop/git/env/local/lib/python2.7/site-packages/django/views/decorators/csrf.py", line 58, in wrapped_view
    return view_func(*args, **kwargs)
  File "/media/ubuntu/OSDisk/Users/jason.c.brown/Desktop/git/env/local/lib/python2.7/site-packages/django/views/generic/base.py", line 68, in view
    return self.dispatch(request, *args, **kwargs)
  File "/media/ubuntu/OSDisk/Users/jason.c.brown/Desktop/git/env/local/lib/python2.7/site-packages/rest_framework/views.py", line 489, in dispatch
    response = self.handle_exception(exc)
  File "/media/ubuntu/OSDisk/Users/jason.c.brown/Desktop/git/env/local/lib/python2.7/site-packages/rest_framework/views.py", line 449, in handle_exception
    self.raise_uncaught_exception(exc)
  File "/media/ubuntu/OSDisk/Users/jason.c.brown/Desktop/git/env/local/lib/python2.7/site-packages/rest_framework/views.py", line 486, in dispatch
    response = handler(request, *args, **kwargs)
  File "/media/ubuntu/OSDisk/Users/jason.c.brown/Desktop/git/env/local/lib/python2.7/site-packages/rest_framework/decorators.py", line 52, in handler
    return func(*args, **kwargs)
  File "/media/ubuntu/OSDisk/Users/jason.c.brown/Desktop/git/netops-api/ops/views.py", line 45, in cmds_list
    return Response(serializer.data)
  File "/media/ubuntu/OSDisk/Users/jason.c.brown/Desktop/git/env/local/lib/python2.7/site-packages/rest_framework/serializers.py", line 739, in data
    ret = super(ListSerializer, self).data
  File "/media/ubuntu/OSDisk/Users/jason.c.brown/Desktop/git/env/local/lib/python2.7/site-packages/rest_framework/serializers.py", line 263, in data
    self._data = self.to_representation(self.instance)
  File "/media/ubuntu/OSDisk/Users/jason.c.brown/Desktop/git/env/local/lib/python2.7/site-packages/rest_framework/serializers.py", line 657, in to_representation
    self.child.to_representation(item) for item in iterable
TypeError: 'ModelBase' object is not iterable
[10/Aug/2017 00:20:37] "GET /ops/cmd/ HTTP/1.1" 500 112516
Not Found: /ops/
[10/Aug/2017 00:20:45] "GET /ops/ HTTP/1.1" 404 4768
Performing system checks...

System check identified no issues (0 silenced).
August 10, 2017 - 00:20:21
Django version 1.11.3, using settings 'api.settings'
Starting development server at http://127.0.0.1:8000/
Quit the server with CONTROL-C.
Internal Server Error: /ops/cmd/
Traceback (most recent call last):
  File "/media/ubuntu/OSDisk/Users/jason.c.brown/Desktop/git/env/local/lib/python2.7/site-packages/django/core/handlers/exception.py", line 41, in inner
    response = get_response(request)
  File "/media/ubuntu/OSDisk/Users/jason.c.brown/Desktop/git/env/local/lib/python2.7/site-packages/django/core/handlers/base.py", line 187, in _get_response
    response = self.process_exception_by_middleware(e, request)
  File "/media/ubuntu/OSDisk/Users/jason.c.brown/Desktop/git/env/local/lib/python2.7/site-packages/django/core/handlers/base.py", line 185, in _get_response
    response = wrapped_callback(request, *callback_args, **callback_kwargs)
  File "/media/ubuntu/OSDisk/Users/jason.c.brown/Desktop/git/env/local/lib/python2.7/site-packages/django/views/decorators/csrf.py", line 58, in wrapped_view
    return view_func(*args, **kwargs)
  File "/media/ubuntu/OSDisk/Users/jason.c.brown/Desktop/git/env/local/lib/python2.7/site-packages/django/views/generic/base.py", line 68, in view
    return self.dispatch(request, *args, **kwargs)
  File "/media/ubuntu/OSDisk/Users/jason.c.brown/Desktop/git/env/local/lib/python2.7/site-packages/rest_framework/views.py", line 489, in dispatch
    response = self.handle_exception(exc)
  File "/media/ubuntu/OSDisk/Users/jason.c.brown/Desktop/git/env/local/lib/python2.7/site-packages/rest_framework/views.py", line 449, in handle_exception
    self.raise_uncaught_exception(exc)
  File "/media/ubuntu/OSDisk/Users/jason.c.brown/Desktop/git/env/local/lib/python2.7/site-packages/rest_framework/views.py", line 486, in dispatch
    response = handler(request, *args, **kwargs)
  File "/media/ubuntu/OSDisk/Users/jason.c.brown/Desktop/git/env/local/lib/python2.7/site-packages/rest_framework/decorators.py", line 52, in handler
    return func(*args, **kwargs)
  File "/media/ubuntu/OSDisk/Users/jason.c.brown/Desktop/git/netops-api/ops/views.py", line 45, in cmds_list
    return Response(serializer.data)
  File "/media/ubuntu/OSDisk/Users/jason.c.brown/Desktop/git/env/local/lib/python2.7/site-packages/rest_framework/serializers.py", line 739, in data
    ret = super(ListSerializer, self).data
  File "/media/ubuntu/OSDisk/Users/jason.c.brown/Desktop/git/env/local/lib/python2.7/site-packages/rest_framework/serializers.py", line 263, in data
    self._data = self.to_representation(self.instance)
  File "/media/ubuntu/OSDisk/Users/jason.c.brown/Desktop/git/env/local/lib/python2.7/site-packages/rest_framework/serializers.py", line 657, in to_representation
    self.child.to_representation(item) for item in iterable
TypeError: 'ModelBase' object is not iterable
[10/Aug/2017 00:22:01] "GET /ops/cmd/ HTTP/1.1" 500 112651
[10/Aug/2017 00:22:05] "GET /ops/cmd/1/ HTTP/1.1" 200 8347
[10/Aug/2017 00:22:05] "GET /static/rest_framework/css/bootstrap-tweaks.css HTTP/1.1" 304 0
[10/Aug/2017 00:22:05] "GET /static/rest_framework/js/ajax-form.js HTTP/1.1" 304 0
[10/Aug/2017 00:22:05] "GET /static/rest_framework/css/bootstrap.min.css HTTP/1.1" 304 0
[10/Aug/2017 00:22:05] "GET /static/rest_framework/css/prettify.css HTTP/1.1" 304 0
[10/Aug/2017 00:22:05] "GET /static/rest_framework/css/default.css HTTP/1.1" 304 0
[10/Aug/2017 00:22:05] "GET /static/rest_framework/js/csrf.js HTTP/1.1" 304 0
[10/Aug/2017 00:22:05] "GET /static/rest_framework/js/default.js HTTP/1.1" 304 0
[10/Aug/2017 00:22:05] "GET /static/rest_framework/js/jquery-1.12.4.min.js HTTP/1.1" 304 0
[10/Aug/2017 00:22:05] "GET /static/rest_framework/js/bootstrap.min.js HTTP/1.1" 304 0
[10/Aug/2017 00:22:05] "GET /static/rest_framework/js/prettify-min.js HTTP/1.1" 304 0
[10/Aug/2017 00:22:05] "GET /static/rest_framework/img/grid.png HTTP/1.1" 304 0
Internal Server Error: /ops/cmd/
Traceback (most recent call last):
  File "/media/ubuntu/OSDisk/Users/jason.c.brown/Desktop/git/env/local/lib/python2.7/site-packages/django/core/handlers/exception.py", line 41, in inner
    response = get_response(request)
  File "/media/ubuntu/OSDisk/Users/jason.c.brown/Desktop/git/env/local/lib/python2.7/site-packages/django/core/handlers/base.py", line 187, in _get_response
    response = self.process_exception_by_middleware(e, request)
  File "/media/ubuntu/OSDisk/Users/jason.c.brown/Desktop/git/env/local/lib/python2.7/site-packages/django/core/handlers/base.py", line 185, in _get_response
    response = wrapped_callback(request, *callback_args, **callback_kwargs)
  File "/media/ubuntu/OSDisk/Users/jason.c.brown/Desktop/git/env/local/lib/python2.7/site-packages/django/views/decorators/csrf.py", line 58, in wrapped_view
    return view_func(*args, **kwargs)
  File "/media/ubuntu/OSDisk/Users/jason.c.brown/Desktop/git/env/local/lib/python2.7/site-packages/django/views/generic/base.py", line 68, in view
    return self.dispatch(request, *args, **kwargs)
  File "/media/ubuntu/OSDisk/Users/jason.c.brown/Desktop/git/env/local/lib/python2.7/site-packages/rest_framework/views.py", line 489, in dispatch
    response = self.handle_exception(exc)
  File "/media/ubuntu/OSDisk/Users/jason.c.brown/Desktop/git/env/local/lib/python2.7/site-packages/rest_framework/views.py", line 449, in handle_exception
    self.raise_uncaught_exception(exc)
  File "/media/ubuntu/OSDisk/Users/jason.c.brown/Desktop/git/env/local/lib/python2.7/site-packages/rest_framework/views.py", line 486, in dispatch
    response = handler(request, *args, **kwargs)
  File "/media/ubuntu/OSDisk/Users/jason.c.brown/Desktop/git/env/local/lib/python2.7/site-packages/rest_framework/decorators.py", line 52, in handler
    return func(*args, **kwargs)
  File "/media/ubuntu/OSDisk/Users/jason.c.brown/Desktop/git/netops-api/ops/views.py", line 45, in cmds_list
    return Response(serializer.data)
  File "/media/ubuntu/OSDisk/Users/jason.c.brown/Desktop/git/env/local/lib/python2.7/site-packages/rest_framework/serializers.py", line 739, in data
    ret = super(ListSerializer, self).data
  File "/media/ubuntu/OSDisk/Users/jason.c.brown/Desktop/git/env/local/lib/python2.7/site-packages/rest_framework/serializers.py", line 263, in data
    self._data = self.to_representation(self.instance)
  File "/media/ubuntu/OSDisk/Users/jason.c.brown/Desktop/git/env/local/lib/python2.7/site-packages/rest_framework/serializers.py", line 657, in to_representation
    self.child.to_representation(item) for item in iterable
TypeError: 'ModelBase' object is not iterable
[10/Aug/2017 00:22:11] "GET /ops/cmd/ HTTP/1.1" 500 112668
[10/Aug/2017 00:22:21] "OPTIONS /ops/cmd/1/ HTTP/1.1" 200 8467
Performing system checks...

System check identified no issues (0 silenced).
August 10, 2017 - 00:21:59
Django version 1.11.3, using settings 'api.settings'
Starting development server at http://127.0.0.1:8000/
Quit the server with CONTROL-C.
Internal Server Error: /ops/cmd/
Traceback (most recent call last):
  File "/media/ubuntu/OSDisk/Users/jason.c.brown/Desktop/git/env/local/lib/python2.7/site-packages/django/core/handlers/exception.py", line 41, in inner
    response = get_response(request)
  File "/media/ubuntu/OSDisk/Users/jason.c.brown/Desktop/git/env/local/lib/python2.7/site-packages/django/core/handlers/base.py", line 187, in _get_response
    response = self.process_exception_by_middleware(e, request)
  File "/media/ubuntu/OSDisk/Users/jason.c.brown/Desktop/git/env/local/lib/python2.7/site-packages/django/core/handlers/base.py", line 185, in _get_response
    response = wrapped_callback(request, *callback_args, **callback_kwargs)
  File "/media/ubuntu/OSDisk/Users/jason.c.brown/Desktop/git/env/local/lib/python2.7/site-packages/django/views/decorators/csrf.py", line 58, in wrapped_view
    return view_func(*args, **kwargs)
  File "/media/ubuntu/OSDisk/Users/jason.c.brown/Desktop/git/env/local/lib/python2.7/site-packages/django/views/generic/base.py", line 68, in view
    return self.dispatch(request, *args, **kwargs)
  File "/media/ubuntu/OSDisk/Users/jason.c.brown/Desktop/git/env/local/lib/python2.7/site-packages/rest_framework/views.py", line 489, in dispatch
    response = self.handle_exception(exc)
  File "/media/ubuntu/OSDisk/Users/jason.c.brown/Desktop/git/env/local/lib/python2.7/site-packages/rest_framework/views.py", line 449, in handle_exception
    self.raise_uncaught_exception(exc)
  File "/media/ubuntu/OSDisk/Users/jason.c.brown/Desktop/git/env/local/lib/python2.7/site-packages/rest_framework/views.py", line 486, in dispatch
    response = handler(request, *args, **kwargs)
  File "/media/ubuntu/OSDisk/Users/jason.c.brown/Desktop/git/env/local/lib/python2.7/site-packages/rest_framework/decorators.py", line 52, in handler
    return func(*args, **kwargs)
  File "/media/ubuntu/OSDisk/Users/jason.c.brown/Desktop/git/netops-api/ops/views.py", line 45, in cmds_list
    return Response(serializer.data)
  File "/media/ubuntu/OSDisk/Users/jason.c.brown/Desktop/git/env/local/lib/python2.7/site-packages/rest_framework/serializers.py", line 739, in data
    ret = super(ListSerializer, self).data
  File "/media/ubuntu/OSDisk/Users/jason.c.brown/Desktop/git/env/local/lib/python2.7/site-packages/rest_framework/serializers.py", line 263, in data
    self._data = self.to_representation(self.instance)
  File "/media/ubuntu/OSDisk/Users/jason.c.brown/Desktop/git/env/local/lib/python2.7/site-packages/rest_framework/serializers.py", line 657, in to_representation
    self.child.to_representation(item) for item in iterable
TypeError: 'ModelBase' object is not iterable
[10/Aug/2017 00:23:48] "GET /ops/cmd/ HTTP/1.1" 500 112668
[10/Aug/2017 00:23:52] "GET / HTTP/1.1" 200 5320
Internal Server Error: /ops/cmd/
Traceback (most recent call last):
  File "/media/ubuntu/OSDisk/Users/jason.c.brown/Desktop/git/env/local/lib/python2.7/site-packages/django/core/handlers/exception.py", line 41, in inner
    response = get_response(request)
  File "/media/ubuntu/OSDisk/Users/jason.c.brown/Desktop/git/env/local/lib/python2.7/site-packages/django/core/handlers/base.py", line 187, in _get_response
    response = self.process_exception_by_middleware(e, request)
  File "/media/ubuntu/OSDisk/Users/jason.c.brown/Desktop/git/env/local/lib/python2.7/site-packages/django/core/handlers/base.py", line 185, in _get_response
    response = wrapped_callback(request, *callback_args, **callback_kwargs)
  File "/media/ubuntu/OSDisk/Users/jason.c.brown/Desktop/git/env/local/lib/python2.7/site-packages/django/views/decorators/csrf.py", line 58, in wrapped_view
    return view_func(*args, **kwargs)
  File "/media/ubuntu/OSDisk/Users/jason.c.brown/Desktop/git/env/local/lib/python2.7/site-packages/django/views/generic/base.py", line 68, in view
    return self.dispatch(request, *args, **kwargs)
  File "/media/ubuntu/OSDisk/Users/jason.c.brown/Desktop/git/env/local/lib/python2.7/site-packages/rest_framework/views.py", line 489, in dispatch
    response = self.handle_exception(exc)
  File "/media/ubuntu/OSDisk/Users/jason.c.brown/Desktop/git/env/local/lib/python2.7/site-packages/rest_framework/views.py", line 449, in handle_exception
    self.raise_uncaught_exception(exc)
  File "/media/ubuntu/OSDisk/Users/jason.c.brown/Desktop/git/env/local/lib/python2.7/site-packages/rest_framework/views.py", line 486, in dispatch
    response = handler(request, *args, **kwargs)
  File "/media/ubuntu/OSDisk/Users/jason.c.brown/Desktop/git/env/local/lib/python2.7/site-packages/rest_framework/decorators.py", line 52, in handler
    return func(*args, **kwargs)
  File "/media/ubuntu/OSDisk/Users/jason.c.brown/Desktop/git/netops-api/ops/views.py", line 45, in cmds_list
    return Response(serializer.data)
  File "/media/ubuntu/OSDisk/Users/jason.c.brown/Desktop/git/env/local/lib/python2.7/site-packages/rest_framework/serializers.py", line 739, in data
    ret = super(ListSerializer, self).data
  File "/media/ubuntu/OSDisk/Users/jason.c.brown/Desktop/git/env/local/lib/python2.7/site-packages/rest_framework/serializers.py", line 263, in data
    self._data = self.to_representation(self.instance)
  File "/media/ubuntu/OSDisk/Users/jason.c.brown/Desktop/git/env/local/lib/python2.7/site-packages/rest_framework/serializers.py", line 657, in to_representation
    self.child.to_representation(item) for item in iterable
TypeError: 'ModelBase' object is not iterable
[10/Aug/2017 00:23:58] "GET /ops/cmd/ HTTP/1.1" 500 112668
Performing system checks...

System check identified no issues (0 silenced).
August 10, 2017 - 00:23:46
Django version 1.11.3, using settings 'api.settings'
Starting development server at http://127.0.0.1:8000/
Quit the server with CONTROL-C.
Performing system checks...

System check identified no issues (0 silenced).
August 10, 2017 - 00:24:07
Django version 1.11.3, using settings 'api.settings'
Starting development server at http://127.0.0.1:8000/
Quit the server with CONTROL-C.
[10/Aug/2017 00:24:29] "GET /ops/cmd/1/ HTTP/1.1" 200 8347
[10/Aug/2017 00:24:29] "GET /static/rest_framework/css/bootstrap.min.css HTTP/1.1" 304 0
[10/Aug/2017 00:24:29] "GET /static/rest_framework/css/bootstrap-tweaks.css HTTP/1.1" 304 0
[10/Aug/2017 00:24:29] "GET /static/rest_framework/css/prettify.css HTTP/1.1" 304 0
[10/Aug/2017 00:24:29] "GET /static/rest_framework/css/default.css HTTP/1.1" 304 0
[10/Aug/2017 00:24:29] "GET /static/rest_framework/js/ajax-form.js HTTP/1.1" 304 0
[10/Aug/2017 00:24:29] "GET /static/rest_framework/js/jquery-1.12.4.min.js HTTP/1.1" 304 0
[10/Aug/2017 00:24:29] "GET /static/rest_framework/js/csrf.js HTTP/1.1" 304 0
[10/Aug/2017 00:24:29] "GET /static/rest_framework/js/bootstrap.min.js HTTP/1.1" 304 0
[10/Aug/2017 00:24:29] "GET /static/rest_framework/js/prettify-min.js HTTP/1.1" 304 0
[10/Aug/2017 00:24:29] "GET /static/rest_framework/js/default.js HTTP/1.1" 304 0
[10/Aug/2017 00:24:29] "GET /static/rest_framework/img/grid.png HTTP/1.1" 304 0
[10/Aug/2017 00:24:34] "GET /ops/cmd/1/ HTTP/1.1" 200 8347
[10/Aug/2017 00:24:35] "GET /static/rest_framework/css/bootstrap.min.css HTTP/1.1" 304 0
[10/Aug/2017 00:24:35] "GET /static/rest_framework/js/ajax-form.js HTTP/1.1" 304 0
[10/Aug/2017 00:24:35] "GET /static/rest_framework/css/default.css HTTP/1.1" 304 0
[10/Aug/2017 00:24:35] "GET /static/rest_framework/js/csrf.js HTTP/1.1" 304 0
[10/Aug/2017 00:24:35] "GET /static/rest_framework/css/prettify.css HTTP/1.1" 304 0
[10/Aug/2017 00:24:35] "GET /static/rest_framework/js/jquery-1.12.4.min.js HTTP/1.1" 304 0
[10/Aug/2017 00:24:35] "GET /static/rest_framework/css/bootstrap-tweaks.css HTTP/1.1" 304 0
[10/Aug/2017 00:24:35] "GET /static/rest_framework/js/default.js HTTP/1.1" 304 0
[10/Aug/2017 00:24:35] "GET /static/rest_framework/js/bootstrap.min.js HTTP/1.1" 304 0
[10/Aug/2017 00:24:35] "GET /static/rest_framework/img/grid.png HTTP/1.1" 304 0
[10/Aug/2017 00:24:35] "GET /static/rest_framework/js/prettify-min.js HTTP/1.1" 304 0
Performing system checks...

System check identified no issues (0 silenced).
August 10, 2017 - 00:24:27
Django version 1.11.3, using settings 'api.settings'
Starting development server at http://127.0.0.1:8000/
Quit the server with CONTROL-C.
[10/Aug/2017 00:24:47] "GET /ops/cmd/1/ HTTP/1.1" 200 8347
[10/Aug/2017 00:24:47] "GET /static/rest_framework/css/default.css HTTP/1.1" 304 0
[10/Aug/2017 00:24:47] "GET /static/rest_framework/js/jquery-1.12.4.min.js HTTP/1.1" 304 0
[10/Aug/2017 00:24:47] "GET /static/rest_framework/css/bootstrap.min.css HTTP/1.1" 304 0
[10/Aug/2017 00:24:47] "GET /static/rest_framework/css/bootstrap-tweaks.css HTTP/1.1" 304 0
[10/Aug/2017 00:24:47] "GET /static/rest_framework/css/prettify.css HTTP/1.1" 304 0
[10/Aug/2017 00:24:47] "GET /static/rest_framework/js/ajax-form.js HTTP/1.1" 304 0
[10/Aug/2017 00:24:47] "GET /static/rest_framework/js/bootstrap.min.js HTTP/1.1" 304 0
[10/Aug/2017 00:24:47] "GET /static/rest_framework/js/csrf.js HTTP/1.1" 304 0
[10/Aug/2017 00:24:47] "GET /static/rest_framework/js/default.js HTTP/1.1" 304 0
[10/Aug/2017 00:24:47] "GET /static/rest_framework/js/prettify-min.js HTTP/1.1" 304 0
[10/Aug/2017 00:24:47] "GET /static/rest_framework/img/grid.png HTTP/1.1" 304 0
[10/Aug/2017 00:24:48] "GET /ops/cmd/1/ HTTP/1.1" 200 8347
[10/Aug/2017 00:24:48] "GET /static/rest_framework/css/bootstrap.min.css HTTP/1.1" 304 0
[10/Aug/2017 00:24:48] "GET /static/rest_framework/css/default.css HTTP/1.1" 304 0
[10/Aug/2017 00:24:48] "GET /static/rest_framework/js/jquery-1.12.4.min.js HTTP/1.1" 304 0
[10/Aug/2017 00:24:48] "GET /static/rest_framework/css/prettify.css HTTP/1.1" 304 0
[10/Aug/2017 00:24:48] "GET /static/rest_framework/js/csrf.js HTTP/1.1" 304 0
[10/Aug/2017 00:24:48] "GET /static/rest_framework/js/ajax-form.js HTTP/1.1" 304 0
[10/Aug/2017 00:24:48] "GET /static/rest_framework/css/bootstrap-tweaks.css HTTP/1.1" 304 0
[10/Aug/2017 00:24:48] "GET /static/rest_framework/js/bootstrap.min.js HTTP/1.1" 304 0
[10/Aug/2017 00:24:48] "GET /static/rest_framework/js/prettify-min.js HTTP/1.1" 304 0
[10/Aug/2017 00:24:48] "GET /static/rest_framework/js/default.js HTTP/1.1" 304 0
[10/Aug/2017 00:24:48] "GET /static/rest_framework/img/grid.png HTTP/1.1" 304 0
[10/Aug/2017 00:24:50] "GET /ops/cmd/1/ HTTP/1.1" 200 8347
[10/Aug/2017 00:24:50] "GET /static/rest_framework/js/ajax-form.js HTTP/1.1" 304 0
[10/Aug/2017 00:24:50] "GET /static/rest_framework/css/bootstrap.min.css HTTP/1.1" 304 0
[10/Aug/2017 00:24:50] "GET /static/rest_framework/js/jquery-1.12.4.min.js HTTP/1.1" 304 0
[10/Aug/2017 00:24:50] "GET /static/rest_framework/css/default.css HTTP/1.1" 304 0
[10/Aug/2017 00:24:50] "GET /static/rest_framework/css/prettify.css HTTP/1.1" 304 0
[10/Aug/2017 00:24:50] "GET /static/rest_framework/css/bootstrap-tweaks.css HTTP/1.1" 304 0
[10/Aug/2017 00:24:50] "GET /static/rest_framework/js/bootstrap.min.js HTTP/1.1" 304 0
[10/Aug/2017 00:24:50] "GET /static/rest_framework/js/csrf.js HTTP/1.1" 304 0
[10/Aug/2017 00:24:50] "GET /static/rest_framework/js/default.js HTTP/1.1" 304 0
[10/Aug/2017 00:24:50] "GET /static/rest_framework/js/prettify-min.js HTTP/1.1" 304 0
[10/Aug/2017 00:24:50] "GET /static/rest_framework/img/grid.png HTTP/1.1" 304 0
[10/Aug/2017 00:24:52] "GET /ops/cmd/1/ HTTP/1.1" 200 8347
[10/Aug/2017 00:24:52] "GET /static/rest_framework/css/bootstrap.min.css HTTP/1.1" 304 0
[10/Aug/2017 00:24:52] "GET /static/rest_framework/css/bootstrap-tweaks.css HTTP/1.1" 304 0
[10/Aug/2017 00:24:52] "GET /static/rest_framework/css/prettify.css HTTP/1.1" 304 0
[10/Aug/2017 00:24:52] "GET /static/rest_framework/js/csrf.js HTTP/1.1" 304 0
[10/Aug/2017 00:24:52] "GET /static/rest_framework/js/ajax-form.js HTTP/1.1" 304 0
[10/Aug/2017 00:24:52] "GET /static/rest_framework/css/default.css HTTP/1.1" 304 0
[10/Aug/2017 00:24:52] "GET /static/rest_framework/js/prettify-min.js HTTP/1.1" 304 0
[10/Aug/2017 00:24:52] "GET /static/rest_framework/js/jquery-1.12.4.min.js HTTP/1.1" 304 0
[10/Aug/2017 00:24:52] "GET /static/rest_framework/js/bootstrap.min.js HTTP/1.1" 304 0
[10/Aug/2017 00:24:52] "GET /static/rest_framework/js/default.js HTTP/1.1" 304 0
[10/Aug/2017 00:24:52] "GET /static/rest_framework/img/grid.png HTTP/1.1" 304 0
[10/Aug/2017 00:24:53] "GET /ops/cmd/1/ HTTP/1.1" 200 8347
[10/Aug/2017 00:24:53] "GET /static/rest_framework/css/bootstrap-tweaks.css HTTP/1.1" 304 0
[10/Aug/2017 00:24:53] "GET /static/rest_framework/css/bootstrap.min.css HTTP/1.1" 304 0
[10/Aug/2017 00:24:53] "GET /static/rest_framework/css/prettify.css HTTP/1.1" 304 0
[10/Aug/2017 00:24:54] "GET /static/rest_framework/css/default.css HTTP/1.1" 304 0
[10/Aug/2017 00:24:54] "GET /static/rest_framework/js/jquery-1.12.4.min.js HTTP/1.1" 304 0
[10/Aug/2017 00:24:54] "GET /static/rest_framework/js/bootstrap.min.js HTTP/1.1" 304 0
[10/Aug/2017 00:24:54] "GET /static/rest_framework/js/prettify-min.js HTTP/1.1" 304 0
[10/Aug/2017 00:24:54] "GET /static/rest_framework/js/csrf.js HTTP/1.1" 304 0
[10/Aug/2017 00:24:54] "GET /static/rest_framework/js/ajax-form.js HTTP/1.1" 304 0
[10/Aug/2017 00:24:54] "GET /static/rest_framework/img/grid.png HTTP/1.1" 304 0
[10/Aug/2017 00:24:54] "GET /static/rest_framework/js/default.js HTTP/1.1" 304 0
[10/Aug/2017 00:24:57] "GET /ops/cmd/2/ HTTP/1.1" 200 8337
[10/Aug/2017 00:25:02] "GET /ops/cmd/1/ HTTP/1.1" 200 8347
Internal Server Error: /ops/cmd/
Traceback (most recent call last):
  File "/media/ubuntu/OSDisk/Users/jason.c.brown/Desktop/git/env/local/lib/python2.7/site-packages/django/core/handlers/exception.py", line 41, in inner
    response = get_response(request)
  File "/media/ubuntu/OSDisk/Users/jason.c.brown/Desktop/git/env/local/lib/python2.7/site-packages/django/core/handlers/base.py", line 187, in _get_response
    response = self.process_exception_by_middleware(e, request)
  File "/media/ubuntu/OSDisk/Users/jason.c.brown/Desktop/git/env/local/lib/python2.7/site-packages/django/core/handlers/base.py", line 185, in _get_response
    response = wrapped_callback(request, *callback_args, **callback_kwargs)
  File "/media/ubuntu/OSDisk/Users/jason.c.brown/Desktop/git/env/local/lib/python2.7/site-packages/django/views/decorators/csrf.py", line 58, in wrapped_view
    return view_func(*args, **kwargs)
  File "/media/ubuntu/OSDisk/Users/jason.c.brown/Desktop/git/env/local/lib/python2.7/site-packages/django/views/generic/base.py", line 68, in view
    return self.dispatch(request, *args, **kwargs)
  File "/media/ubuntu/OSDisk/Users/jason.c.brown/Desktop/git/env/local/lib/python2.7/site-packages/rest_framework/views.py", line 489, in dispatch
    response = self.handle_exception(exc)
  File "/media/ubuntu/OSDisk/Users/jason.c.brown/Desktop/git/env/local/lib/python2.7/site-packages/rest_framework/views.py", line 449, in handle_exception
    self.raise_uncaught_exception(exc)
  File "/media/ubuntu/OSDisk/Users/jason.c.brown/Desktop/git/env/local/lib/python2.7/site-packages/rest_framework/views.py", line 486, in dispatch
    response = handler(request, *args, **kwargs)
  File "/media/ubuntu/OSDisk/Users/jason.c.brown/Desktop/git/env/local/lib/python2.7/site-packages/rest_framework/decorators.py", line 52, in handler
    return func(*args, **kwargs)
  File "/media/ubuntu/OSDisk/Users/jason.c.brown/Desktop/git/netops-api/ops/views.py", line 45, in cmds_list
    return Response(serializer.data)
  File "/media/ubuntu/OSDisk/Users/jason.c.brown/Desktop/git/env/local/lib/python2.7/site-packages/rest_framework/serializers.py", line 739, in data
    ret = super(ListSerializer, self).data
  File "/media/ubuntu/OSDisk/Users/jason.c.brown/Desktop/git/env/local/lib/python2.7/site-packages/rest_framework/serializers.py", line 263, in data
    self._data = self.to_representation(self.instance)
  File "/media/ubuntu/OSDisk/Users/jason.c.brown/Desktop/git/env/local/lib/python2.7/site-packages/rest_framework/serializers.py", line 657, in to_representation
    self.child.to_representation(item) for item in iterable
TypeError: 'ModelBase' object is not iterable
[10/Aug/2017 00:25:08] "GET /ops/cmd/ HTTP/1.1" 500 112516
[10/Aug/2017 00:25:11] "GET /ops/cmd/1/ HTTP/1.1" 200 8347
[10/Aug/2017 00:25:11] "GET /static/rest_framework/css/bootstrap.min.css HTTP/1.1" 304 0
[10/Aug/2017 00:25:11] "GET /static/rest_framework/js/ajax-form.js HTTP/1.1" 304 0
[10/Aug/2017 00:25:11] "GET /static/rest_framework/css/default.css HTTP/1.1" 304 0
[10/Aug/2017 00:25:11] "GET /static/rest_framework/js/jquery-1.12.4.min.js HTTP/1.1" 304 0
[10/Aug/2017 00:25:12] "GET /static/rest_framework/js/csrf.js HTTP/1.1" 304 0
[10/Aug/2017 00:25:12] "GET /static/rest_framework/css/bootstrap-tweaks.css HTTP/1.1" 304 0
[10/Aug/2017 00:25:12] "GET /static/rest_framework/css/prettify.css HTTP/1.1" 304 0
[10/Aug/2017 00:25:12] "GET /static/rest_framework/js/bootstrap.min.js HTTP/1.1" 304 0
[10/Aug/2017 00:25:12] "GET /static/rest_framework/js/prettify-min.js HTTP/1.1" 304 0
[10/Aug/2017 00:25:12] "GET /static/rest_framework/img/grid.png HTTP/1.1" 304 0
[10/Aug/2017 00:25:12] "GET /static/rest_framework/js/default.js HTTP/1.1" 304 0
Internal Server Error: /ops/cmd/
Traceback (most recent call last):
  File "/media/ubuntu/OSDisk/Users/jason.c.brown/Desktop/git/env/local/lib/python2.7/site-packages/django/core/handlers/exception.py", line 41, in inner
    response = get_response(request)
  File "/media/ubuntu/OSDisk/Users/jason.c.brown/Desktop/git/env/local/lib/python2.7/site-packages/django/core/handlers/base.py", line 187, in _get_response
    response = self.process_exception_by_middleware(e, request)
  File "/media/ubuntu/OSDisk/Users/jason.c.brown/Desktop/git/env/local/lib/python2.7/site-packages/django/core/handlers/base.py", line 185, in _get_response
    response = wrapped_callback(request, *callback_args, **callback_kwargs)
  File "/media/ubuntu/OSDisk/Users/jason.c.brown/Desktop/git/env/local/lib/python2.7/site-packages/django/views/decorators/csrf.py", line 58, in wrapped_view
    return view_func(*args, **kwargs)
  File "/media/ubuntu/OSDisk/Users/jason.c.brown/Desktop/git/env/local/lib/python2.7/site-packages/django/views/generic/base.py", line 68, in view
    return self.dispatch(request, *args, **kwargs)
  File "/media/ubuntu/OSDisk/Users/jason.c.brown/Desktop/git/env/local/lib/python2.7/site-packages/rest_framework/views.py", line 489, in dispatch
    response = self.handle_exception(exc)
  File "/media/ubuntu/OSDisk/Users/jason.c.brown/Desktop/git/env/local/lib/python2.7/site-packages/rest_framework/views.py", line 449, in handle_exception
    self.raise_uncaught_exception(exc)
  File "/media/ubuntu/OSDisk/Users/jason.c.brown/Desktop/git/env/local/lib/python2.7/site-packages/rest_framework/views.py", line 486, in dispatch
    response = handler(request, *args, **kwargs)
  File "/media/ubuntu/OSDisk/Users/jason.c.brown/Desktop/git/env/local/lib/python2.7/site-packages/rest_framework/decorators.py", line 52, in handler
    return func(*args, **kwargs)
  File "/media/ubuntu/OSDisk/Users/jason.c.brown/Desktop/git/netops-api/ops/views.py", line 45, in cmds_list
    return Response(serializer.data)
  File "/media/ubuntu/OSDisk/Users/jason.c.brown/Desktop/git/env/local/lib/python2.7/site-packages/rest_framework/serializers.py", line 739, in data
    ret = super(ListSerializer, self).data
  File "/media/ubuntu/OSDisk/Users/jason.c.brown/Desktop/git/env/local/lib/python2.7/site-packages/rest_framework/serializers.py", line 263, in data
    self._data = self.to_representation(self.instance)
  File "/media/ubuntu/OSDisk/Users/jason.c.brown/Desktop/git/env/local/lib/python2.7/site-packages/rest_framework/serializers.py", line 657, in to_representation
    self.child.to_representation(item) for item in iterable
TypeError: 'ModelBase' object is not iterable
[10/Aug/2017 00:25:15] "GET /ops/cmd/ HTTP/1.1" 500 112651
Internal Server Error: /ops/cmd/
Traceback (most recent call last):
  File "/media/ubuntu/OSDisk/Users/jason.c.brown/Desktop/git/env/local/lib/python2.7/site-packages/django/core/handlers/exception.py", line 41, in inner
    response = get_response(request)
  File "/media/ubuntu/OSDisk/Users/jason.c.brown/Desktop/git/env/local/lib/python2.7/site-packages/django/core/handlers/base.py", line 187, in _get_response
    response = self.process_exception_by_middleware(e, request)
  File "/media/ubuntu/OSDisk/Users/jason.c.brown/Desktop/git/env/local/lib/python2.7/site-packages/django/core/handlers/base.py", line 185, in _get_response
    response = wrapped_callback(request, *callback_args, **callback_kwargs)
  File "/media/ubuntu/OSDisk/Users/jason.c.brown/Desktop/git/env/local/lib/python2.7/site-packages/django/views/decorators/csrf.py", line 58, in wrapped_view
    return view_func(*args, **kwargs)
  File "/media/ubuntu/OSDisk/Users/jason.c.brown/Desktop/git/env/local/lib/python2.7/site-packages/django/views/generic/base.py", line 68, in view
    return self.dispatch(request, *args, **kwargs)
  File "/media/ubuntu/OSDisk/Users/jason.c.brown/Desktop/git/env/local/lib/python2.7/site-packages/rest_framework/views.py", line 489, in dispatch
    response = self.handle_exception(exc)
  File "/media/ubuntu/OSDisk/Users/jason.c.brown/Desktop/git/env/local/lib/python2.7/site-packages/rest_framework/views.py", line 449, in handle_exception
    self.raise_uncaught_exception(exc)
  File "/media/ubuntu/OSDisk/Users/jason.c.brown/Desktop/git/env/local/lib/python2.7/site-packages/rest_framework/views.py", line 486, in dispatch
    response = handler(request, *args, **kwargs)
  File "/media/ubuntu/OSDisk/Users/jason.c.brown/Desktop/git/env/local/lib/python2.7/site-packages/rest_framework/decorators.py", line 52, in handler
    return func(*args, **kwargs)
  File "/media/ubuntu/OSDisk/Users/jason.c.brown/Desktop/git/netops-api/ops/views.py", line 45, in cmds_list
    return Response(serializer.data)
  File "/media/ubuntu/OSDisk/Users/jason.c.brown/Desktop/git/env/local/lib/python2.7/site-packages/rest_framework/serializers.py", line 739, in data
    ret = super(ListSerializer, self).data
  File "/media/ubuntu/OSDisk/Users/jason.c.brown/Desktop/git/env/local/lib/python2.7/site-packages/rest_framework/serializers.py", line 263, in data
    self._data = self.to_representation(self.instance)
  File "/media/ubuntu/OSDisk/Users/jason.c.brown/Desktop/git/env/local/lib/python2.7/site-packages/rest_framework/serializers.py", line 657, in to_representation
    self.child.to_representation(item) for item in iterable
TypeError: 'ModelBase' object is not iterable
[10/Aug/2017 00:27:05] "GET /ops/cmd/ HTTP/1.1" 500 112651
Performing system checks...

System check identified no issues (0 silenced).
August 10, 2017 - 00:24:43
Django version 1.11.3, using settings 'api.settings'
Starting development server at http://127.0.0.1:8000/
Quit the server with CONTROL-C.
Internal Server Error: /ops/cmd/
Traceback (most recent call last):
  File "/media/ubuntu/OSDisk/Users/jason.c.brown/Desktop/git/env/local/lib/python2.7/site-packages/django/core/handlers/exception.py", line 41, in inner
    response = get_response(request)
  File "/media/ubuntu/OSDisk/Users/jason.c.brown/Desktop/git/env/local/lib/python2.7/site-packages/django/core/handlers/base.py", line 187, in _get_response
    response = self.process_exception_by_middleware(e, request)
  File "/media/ubuntu/OSDisk/Users/jason.c.brown/Desktop/git/env/local/lib/python2.7/site-packages/django/core/handlers/base.py", line 185, in _get_response
    response = wrapped_callback(request, *callback_args, **callback_kwargs)
  File "/media/ubuntu/OSDisk/Users/jason.c.brown/Desktop/git/env/local/lib/python2.7/site-packages/django/views/decorators/csrf.py", line 58, in wrapped_view
    return view_func(*args, **kwargs)
  File "/media/ubuntu/OSDisk/Users/jason.c.brown/Desktop/git/env/local/lib/python2.7/site-packages/django/views/generic/base.py", line 68, in view
    return self.dispatch(request, *args, **kwargs)
  File "/media/ubuntu/OSDisk/Users/jason.c.brown/Desktop/git/env/local/lib/python2.7/site-packages/rest_framework/views.py", line 489, in dispatch
    response = self.handle_exception(exc)
  File "/media/ubuntu/OSDisk/Users/jason.c.brown/Desktop/git/env/local/lib/python2.7/site-packages/rest_framework/views.py", line 449, in handle_exception
    self.raise_uncaught_exception(exc)
  File "/media/ubuntu/OSDisk/Users/jason.c.brown/Desktop/git/env/local/lib/python2.7/site-packages/rest_framework/views.py", line 486, in dispatch
    response = handler(request, *args, **kwargs)
  File "/media/ubuntu/OSDisk/Users/jason.c.brown/Desktop/git/env/local/lib/python2.7/site-packages/rest_framework/decorators.py", line 52, in handler
    return func(*args, **kwargs)
  File "/media/ubuntu/OSDisk/Users/jason.c.brown/Desktop/git/netops-api/ops/views.py", line 45, in cmds_list
    return Response(serializer.data)
  File "/media/ubuntu/OSDisk/Users/jason.c.brown/Desktop/git/env/local/lib/python2.7/site-packages/rest_framework/serializers.py", line 739, in data
    ret = super(ListSerializer, self).data
  File "/media/ubuntu/OSDisk/Users/jason.c.brown/Desktop/git/env/local/lib/python2.7/site-packages/rest_framework/serializers.py", line 263, in data
    self._data = self.to_representation(self.instance)
  File "/media/ubuntu/OSDisk/Users/jason.c.brown/Desktop/git/env/local/lib/python2.7/site-packages/rest_framework/serializers.py", line 657, in to_representation
    self.child.to_representation(item) for item in iterable
TypeError: 'ModelBase' object is not iterable
[10/Aug/2017 00:28:46] "GET /ops/cmd/ HTTP/1.1" 500 111467
Internal Server Error: /ops/cmd/
Traceback (most recent call last):
  File "/media/ubuntu/OSDisk/Users/jason.c.brown/Desktop/git/env/local/lib/python2.7/site-packages/django/core/handlers/exception.py", line 41, in inner
    response = get_response(request)
  File "/media/ubuntu/OSDisk/Users/jason.c.brown/Desktop/git/env/local/lib/python2.7/site-packages/django/core/handlers/base.py", line 187, in _get_response
    response = self.process_exception_by_middleware(e, request)
  File "/media/ubuntu/OSDisk/Users/jason.c.brown/Desktop/git/env/local/lib/python2.7/site-packages/django/core/handlers/base.py", line 185, in _get_response
    response = wrapped_callback(request, *callback_args, **callback_kwargs)
  File "/media/ubuntu/OSDisk/Users/jason.c.brown/Desktop/git/env/local/lib/python2.7/site-packages/django/views/decorators/csrf.py", line 58, in wrapped_view
    return view_func(*args, **kwargs)
  File "/media/ubuntu/OSDisk/Users/jason.c.brown/Desktop/git/env/local/lib/python2.7/site-packages/django/views/generic/base.py", line 68, in view
    return self.dispatch(request, *args, **kwargs)
  File "/media/ubuntu/OSDisk/Users/jason.c.brown/Desktop/git/env/local/lib/python2.7/site-packages/rest_framework/views.py", line 489, in dispatch
    response = self.handle_exception(exc)
  File "/media/ubuntu/OSDisk/Users/jason.c.brown/Desktop/git/env/local/lib/python2.7/site-packages/rest_framework/views.py", line 449, in handle_exception
    self.raise_uncaught_exception(exc)
  File "/media/ubuntu/OSDisk/Users/jason.c.brown/Desktop/git/env/local/lib/python2.7/site-packages/rest_framework/views.py", line 486, in dispatch
    response = handler(request, *args, **kwargs)
  File "/media/ubuntu/OSDisk/Users/jason.c.brown/Desktop/git/env/local/lib/python2.7/site-packages/rest_framework/decorators.py", line 52, in handler
    return func(*args, **kwargs)
  File "/media/ubuntu/OSDisk/Users/jason.c.brown/Desktop/git/netops-api/ops/views.py", line 45, in cmds_list
    return Response(serializer.data)
  File "/media/ubuntu/OSDisk/Users/jason.c.brown/Desktop/git/env/local/lib/python2.7/site-packages/rest_framework/serializers.py", line 739, in data
    ret = super(ListSerializer, self).data
  File "/media/ubuntu/OSDisk/Users/jason.c.brown/Desktop/git/env/local/lib/python2.7/site-packages/rest_framework/serializers.py", line 263, in data
    self._data = self.to_representation(self.instance)
  File "/media/ubuntu/OSDisk/Users/jason.c.brown/Desktop/git/env/local/lib/python2.7/site-packages/rest_framework/serializers.py", line 657, in to_representation
    self.child.to_representation(item) for item in iterable
TypeError: 'ModelBase' object is not iterable
[10/Aug/2017 00:28:51] "GET /ops/cmd/ HTTP/1.1" 500 111467
Internal Server Error: /ops/cmd/
Traceback (most recent call last):
  File "/media/ubuntu/OSDisk/Users/jason.c.brown/Desktop/git/env/local/lib/python2.7/site-packages/django/core/handlers/exception.py", line 41, in inner
    response = get_response(request)
  File "/media/ubuntu/OSDisk/Users/jason.c.brown/Desktop/git/env/local/lib/python2.7/site-packages/django/core/handlers/base.py", line 187, in _get_response
    response = self.process_exception_by_middleware(e, request)
  File "/media/ubuntu/OSDisk/Users/jason.c.brown/Desktop/git/env/local/lib/python2.7/site-packages/django/core/handlers/base.py", line 185, in _get_response
    response = wrapped_callback(request, *callback_args, **callback_kwargs)
  File "/media/ubuntu/OSDisk/Users/jason.c.brown/Desktop/git/env/local/lib/python2.7/site-packages/django/views/decorators/csrf.py", line 58, in wrapped_view
    return view_func(*args, **kwargs)
  File "/media/ubuntu/OSDisk/Users/jason.c.brown/Desktop/git/env/local/lib/python2.7/site-packages/django/views/generic/base.py", line 68, in view
    return self.dispatch(request, *args, **kwargs)
  File "/media/ubuntu/OSDisk/Users/jason.c.brown/Desktop/git/env/local/lib/python2.7/site-packages/rest_framework/views.py", line 489, in dispatch
    response = self.handle_exception(exc)
  File "/media/ubuntu/OSDisk/Users/jason.c.brown/Desktop/git/env/local/lib/python2.7/site-packages/rest_framework/views.py", line 449, in handle_exception
    self.raise_uncaught_exception(exc)
  File "/media/ubuntu/OSDisk/Users/jason.c.brown/Desktop/git/env/local/lib/python2.7/site-packages/rest_framework/views.py", line 486, in dispatch
    response = handler(request, *args, **kwargs)
  File "/media/ubuntu/OSDisk/Users/jason.c.brown/Desktop/git/env/local/lib/python2.7/site-packages/rest_framework/decorators.py", line 52, in handler
    return func(*args, **kwargs)
  File "/media/ubuntu/OSDisk/Users/jason.c.brown/Desktop/git/netops-api/ops/views.py", line 45, in cmds_list
    return Response(serializer.data)
  File "/media/ubuntu/OSDisk/Users/jason.c.brown/Desktop/git/env/local/lib/python2.7/site-packages/rest_framework/serializers.py", line 739, in data
    ret = super(ListSerializer, self).data
  File "/media/ubuntu/OSDisk/Users/jason.c.brown/Desktop/git/env/local/lib/python2.7/site-packages/rest_framework/serializers.py", line 263, in data
    self._data = self.to_representation(self.instance)
  File "/media/ubuntu/OSDisk/Users/jason.c.brown/Desktop/git/env/local/lib/python2.7/site-packages/rest_framework/serializers.py", line 657, in to_representation
    self.child.to_representation(item) for item in iterable
TypeError: 'ModelBase' object is not iterable
[10/Aug/2017 00:28:53] "GET /ops/cmd/ HTTP/1.1" 500 111467
Performing system checks...

System check identified no issues (0 silenced).
August 10, 2017 - 00:28:43
Django version 1.11.3, using settings 'api.settings'
Starting development server at http://127.0.0.1:8000/
Quit the server with CONTROL-C.
Performing system checks...

System check identified no issues (0 silenced).
August 10, 2017 - 00:29:06
Django version 1.11.3, using settings 'api.settings'
Starting development server at http://127.0.0.1:8000/
Quit the server with CONTROL-C.
Internal Server Error: /ops/cmd/
Traceback (most recent call last):
  File "/media/ubuntu/OSDisk/Users/jason.c.brown/Desktop/git/env/local/lib/python2.7/site-packages/django/core/handlers/exception.py", line 41, in inner
    response = get_response(request)
  File "/media/ubuntu/OSDisk/Users/jason.c.brown/Desktop/git/env/local/lib/python2.7/site-packages/django/core/handlers/base.py", line 187, in _get_response
    response = self.process_exception_by_middleware(e, request)
  File "/media/ubuntu/OSDisk/Users/jason.c.brown/Desktop/git/env/local/lib/python2.7/site-packages/django/core/handlers/base.py", line 185, in _get_response
    response = wrapped_callback(request, *callback_args, **callback_kwargs)
  File "/media/ubuntu/OSDisk/Users/jason.c.brown/Desktop/git/env/local/lib/python2.7/site-packages/django/views/decorators/csrf.py", line 58, in wrapped_view
    return view_func(*args, **kwargs)
  File "/media/ubuntu/OSDisk/Users/jason.c.brown/Desktop/git/env/local/lib/python2.7/site-packages/django/views/generic/base.py", line 68, in view
    return self.dispatch(request, *args, **kwargs)
  File "/media/ubuntu/OSDisk/Users/jason.c.brown/Desktop/git/env/local/lib/python2.7/site-packages/rest_framework/views.py", line 489, in dispatch
    response = self.handle_exception(exc)
  File "/media/ubuntu/OSDisk/Users/jason.c.brown/Desktop/git/env/local/lib/python2.7/site-packages/rest_framework/views.py", line 449, in handle_exception
    self.raise_uncaught_exception(exc)
  File "/media/ubuntu/OSDisk/Users/jason.c.brown/Desktop/git/env/local/lib/python2.7/site-packages/rest_framework/views.py", line 486, in dispatch
    response = handler(request, *args, **kwargs)
  File "/media/ubuntu/OSDisk/Users/jason.c.brown/Desktop/git/env/local/lib/python2.7/site-packages/rest_framework/decorators.py", line 52, in handler
    return func(*args, **kwargs)
  File "/media/ubuntu/OSDisk/Users/jason.c.brown/Desktop/git/netops-api/ops/views.py", line 45, in cmds_list
    return Response(serializer.data)
  File "/media/ubuntu/OSDisk/Users/jason.c.brown/Desktop/git/env/local/lib/python2.7/site-packages/rest_framework/serializers.py", line 534, in data
    ret = super(Serializer, self).data
  File "/media/ubuntu/OSDisk/Users/jason.c.brown/Desktop/git/env/local/lib/python2.7/site-packages/rest_framework/serializers.py", line 263, in data
    self._data = self.to_representation(self.instance)
  File "/media/ubuntu/OSDisk/Users/jason.c.brown/Desktop/git/env/local/lib/python2.7/site-packages/rest_framework/serializers.py", line 501, in to_representation
    ret[field.field_name] = field.to_representation(attribute)
  File "/media/ubuntu/OSDisk/Users/jason.c.brown/Desktop/git/env/local/lib/python2.7/site-packages/rest_framework/fields.py", line 913, in to_representation
    return int(value)
TypeError: int() argument must be a string or a number, not 'DeferredAttribute'
[10/Aug/2017 00:34:20] "GET /ops/cmd/ HTTP/1.1" 500 118116
Internal Server Error: /ops/cmd/
Traceback (most recent call last):
  File "/media/ubuntu/OSDisk/Users/jason.c.brown/Desktop/git/env/local/lib/python2.7/site-packages/django/core/handlers/exception.py", line 41, in inner
    response = get_response(request)
  File "/media/ubuntu/OSDisk/Users/jason.c.brown/Desktop/git/env/local/lib/python2.7/site-packages/django/core/handlers/base.py", line 187, in _get_response
    response = self.process_exception_by_middleware(e, request)
  File "/media/ubuntu/OSDisk/Users/jason.c.brown/Desktop/git/env/local/lib/python2.7/site-packages/django/core/handlers/base.py", line 185, in _get_response
    response = wrapped_callback(request, *callback_args, **callback_kwargs)
  File "/media/ubuntu/OSDisk/Users/jason.c.brown/Desktop/git/env/local/lib/python2.7/site-packages/django/views/decorators/csrf.py", line 58, in wrapped_view
    return view_func(*args, **kwargs)
  File "/media/ubuntu/OSDisk/Users/jason.c.brown/Desktop/git/env/local/lib/python2.7/site-packages/django/views/generic/base.py", line 68, in view
    return self.dispatch(request, *args, **kwargs)
  File "/media/ubuntu/OSDisk/Users/jason.c.brown/Desktop/git/env/local/lib/python2.7/site-packages/rest_framework/views.py", line 489, in dispatch
    response = self.handle_exception(exc)
  File "/media/ubuntu/OSDisk/Users/jason.c.brown/Desktop/git/env/local/lib/python2.7/site-packages/rest_framework/views.py", line 449, in handle_exception
    self.raise_uncaught_exception(exc)
  File "/media/ubuntu/OSDisk/Users/jason.c.brown/Desktop/git/env/local/lib/python2.7/site-packages/rest_framework/views.py", line 486, in dispatch
    response = handler(request, *args, **kwargs)
  File "/media/ubuntu/OSDisk/Users/jason.c.brown/Desktop/git/env/local/lib/python2.7/site-packages/rest_framework/decorators.py", line 52, in handler
    return func(*args, **kwargs)
  File "/media/ubuntu/OSDisk/Users/jason.c.brown/Desktop/git/netops-api/ops/views.py", line 45, in cmds_list
    return Response(serializer.data)
  File "/media/ubuntu/OSDisk/Users/jason.c.brown/Desktop/git/env/local/lib/python2.7/site-packages/rest_framework/serializers.py", line 534, in data
    ret = super(Serializer, self).data
  File "/media/ubuntu/OSDisk/Users/jason.c.brown/Desktop/git/env/local/lib/python2.7/site-packages/rest_framework/serializers.py", line 263, in data
    self._data = self.to_representation(self.instance)
  File "/media/ubuntu/OSDisk/Users/jason.c.brown/Desktop/git/env/local/lib/python2.7/site-packages/rest_framework/serializers.py", line 501, in to_representation
    ret[field.field_name] = field.to_representation(attribute)
  File "/media/ubuntu/OSDisk/Users/jason.c.brown/Desktop/git/env/local/lib/python2.7/site-packages/rest_framework/fields.py", line 913, in to_representation
    return int(value)
TypeError: int() argument must be a string or a number, not 'DeferredAttribute'
[10/Aug/2017 00:34:23] "GET /ops/cmd/ HTTP/1.1" 500 118116
Internal Server Error: /ops/cmd/
Traceback (most recent call last):
  File "/media/ubuntu/OSDisk/Users/jason.c.brown/Desktop/git/env/local/lib/python2.7/site-packages/django/core/handlers/exception.py", line 41, in inner
    response = get_response(request)
  File "/media/ubuntu/OSDisk/Users/jason.c.brown/Desktop/git/env/local/lib/python2.7/site-packages/django/core/handlers/base.py", line 187, in _get_response
    response = self.process_exception_by_middleware(e, request)
  File "/media/ubuntu/OSDisk/Users/jason.c.brown/Desktop/git/env/local/lib/python2.7/site-packages/django/core/handlers/base.py", line 185, in _get_response
    response = wrapped_callback(request, *callback_args, **callback_kwargs)
  File "/media/ubuntu/OSDisk/Users/jason.c.brown/Desktop/git/env/local/lib/python2.7/site-packages/django/views/decorators/csrf.py", line 58, in wrapped_view
    return view_func(*args, **kwargs)
  File "/media/ubuntu/OSDisk/Users/jason.c.brown/Desktop/git/env/local/lib/python2.7/site-packages/django/views/generic/base.py", line 68, in view
    return self.dispatch(request, *args, **kwargs)
  File "/media/ubuntu/OSDisk/Users/jason.c.brown/Desktop/git/env/local/lib/python2.7/site-packages/rest_framework/views.py", line 489, in dispatch
    response = self.handle_exception(exc)
  File "/media/ubuntu/OSDisk/Users/jason.c.brown/Desktop/git/env/local/lib/python2.7/site-packages/rest_framework/views.py", line 449, in handle_exception
    self.raise_uncaught_exception(exc)
  File "/media/ubuntu/OSDisk/Users/jason.c.brown/Desktop/git/env/local/lib/python2.7/site-packages/rest_framework/views.py", line 486, in dispatch
    response = handler(request, *args, **kwargs)
  File "/media/ubuntu/OSDisk/Users/jason.c.brown/Desktop/git/env/local/lib/python2.7/site-packages/rest_framework/decorators.py", line 52, in handler
    return func(*args, **kwargs)
  File "/media/ubuntu/OSDisk/Users/jason.c.brown/Desktop/git/netops-api/ops/views.py", line 45, in cmds_list
    return Response(serializer.data)
  File "/media/ubuntu/OSDisk/Users/jason.c.brown/Desktop/git/env/local/lib/python2.7/site-packages/rest_framework/serializers.py", line 534, in data
    ret = super(Serializer, self).data
  File "/media/ubuntu/OSDisk/Users/jason.c.brown/Desktop/git/env/local/lib/python2.7/site-packages/rest_framework/serializers.py", line 263, in data
    self._data = self.to_representation(self.instance)
  File "/media/ubuntu/OSDisk/Users/jason.c.brown/Desktop/git/env/local/lib/python2.7/site-packages/rest_framework/serializers.py", line 501, in to_representation
    ret[field.field_name] = field.to_representation(attribute)
  File "/media/ubuntu/OSDisk/Users/jason.c.brown/Desktop/git/env/local/lib/python2.7/site-packages/rest_framework/fields.py", line 913, in to_representation
    return int(value)
TypeError: int() argument must be a string or a number, not 'DeferredAttribute'
[10/Aug/2017 00:34:26] "GET /ops/cmd/ HTTP/1.1" 500 118116
Internal Server Error: /ops/cmd/
Traceback (most recent call last):
  File "/media/ubuntu/OSDisk/Users/jason.c.brown/Desktop/git/env/local/lib/python2.7/site-packages/django/core/handlers/exception.py", line 41, in inner
    response = get_response(request)
  File "/media/ubuntu/OSDisk/Users/jason.c.brown/Desktop/git/env/local/lib/python2.7/site-packages/django/core/handlers/base.py", line 187, in _get_response
    response = self.process_exception_by_middleware(e, request)
  File "/media/ubuntu/OSDisk/Users/jason.c.brown/Desktop/git/env/local/lib/python2.7/site-packages/django/core/handlers/base.py", line 185, in _get_response
    response = wrapped_callback(request, *callback_args, **callback_kwargs)
  File "/media/ubuntu/OSDisk/Users/jason.c.brown/Desktop/git/env/local/lib/python2.7/site-packages/django/views/decorators/csrf.py", line 58, in wrapped_view
    return view_func(*args, **kwargs)
  File "/media/ubuntu/OSDisk/Users/jason.c.brown/Desktop/git/env/local/lib/python2.7/site-packages/django/views/generic/base.py", line 68, in view
    return self.dispatch(request, *args, **kwargs)
  File "/media/ubuntu/OSDisk/Users/jason.c.brown/Desktop/git/env/local/lib/python2.7/site-packages/rest_framework/views.py", line 489, in dispatch
    response = self.handle_exception(exc)
  File "/media/ubuntu/OSDisk/Users/jason.c.brown/Desktop/git/env/local/lib/python2.7/site-packages/rest_framework/views.py", line 449, in handle_exception
    self.raise_uncaught_exception(exc)
  File "/media/ubuntu/OSDisk/Users/jason.c.brown/Desktop/git/env/local/lib/python2.7/site-packages/rest_framework/views.py", line 486, in dispatch
    response = handler(request, *args, **kwargs)
  File "/media/ubuntu/OSDisk/Users/jason.c.brown/Desktop/git/env/local/lib/python2.7/site-packages/rest_framework/decorators.py", line 52, in handler
    return func(*args, **kwargs)
  File "/media/ubuntu/OSDisk/Users/jason.c.brown/Desktop/git/netops-api/ops/views.py", line 45, in cmds_list
    return Response(serializer.data)
  File "/media/ubuntu/OSDisk/Users/jason.c.brown/Desktop/git/env/local/lib/python2.7/site-packages/rest_framework/serializers.py", line 534, in data
    ret = super(Serializer, self).data
  File "/media/ubuntu/OSDisk/Users/jason.c.brown/Desktop/git/env/local/lib/python2.7/site-packages/rest_framework/serializers.py", line 263, in data
    self._data = self.to_representation(self.instance)
  File "/media/ubuntu/OSDisk/Users/jason.c.brown/Desktop/git/env/local/lib/python2.7/site-packages/rest_framework/serializers.py", line 501, in to_representation
    ret[field.field_name] = field.to_representation(attribute)
  File "/media/ubuntu/OSDisk/Users/jason.c.brown/Desktop/git/env/local/lib/python2.7/site-packages/rest_framework/fields.py", line 913, in to_representation
    return int(value)
TypeError: int() argument must be a string or a number, not 'DeferredAttribute'
[10/Aug/2017 00:34:30] "GET /ops/cmd/ HTTP/1.1" 500 118116
[10/Aug/2017 00:35:55] "GET /ops/cmd/1/ HTTP/1.1" 200 8347
[10/Aug/2017 00:36:02] "DELETE /ops/cmd/1/ HTTP/1.1" 200 8114
[10/Aug/2017 00:36:07] "GET /ops/cmd/2/ HTTP/1.1" 200 8337
[10/Aug/2017 00:36:24] "PUT /ops/cmd/2/ HTTP/1.1" 400 8279
[10/Aug/2017 00:36:39] "PUT /ops/cmd/2/ HTTP/1.1" 400 8279
[10/Aug/2017 00:36:56] "PUT /ops/cmd/2/ HTTP/1.1" 200 8343
[10/Aug/2017 00:37:22] "PUT /ops/cmd/2/ HTTP/1.1" 200 8345
Internal Server Error: /ops/cmd/
Traceback (most recent call last):
  File "/media/ubuntu/OSDisk/Users/jason.c.brown/Desktop/git/env/local/lib/python2.7/site-packages/django/core/handlers/exception.py", line 41, in inner
    response = get_response(request)
  File "/media/ubuntu/OSDisk/Users/jason.c.brown/Desktop/git/env/local/lib/python2.7/site-packages/django/core/handlers/base.py", line 187, in _get_response
    response = self.process_exception_by_middleware(e, request)
  File "/media/ubuntu/OSDisk/Users/jason.c.brown/Desktop/git/env/local/lib/python2.7/site-packages/django/core/handlers/base.py", line 185, in _get_response
    response = wrapped_callback(request, *callback_args, **callback_kwargs)
  File "/media/ubuntu/OSDisk/Users/jason.c.brown/Desktop/git/env/local/lib/python2.7/site-packages/django/views/decorators/csrf.py", line 58, in wrapped_view
    return view_func(*args, **kwargs)
  File "/media/ubuntu/OSDisk/Users/jason.c.brown/Desktop/git/env/local/lib/python2.7/site-packages/django/views/generic/base.py", line 68, in view
    return self.dispatch(request, *args, **kwargs)
  File "/media/ubuntu/OSDisk/Users/jason.c.brown/Desktop/git/env/local/lib/python2.7/site-packages/rest_framework/views.py", line 489, in dispatch
    response = self.handle_exception(exc)
  File "/media/ubuntu/OSDisk/Users/jason.c.brown/Desktop/git/env/local/lib/python2.7/site-packages/rest_framework/views.py", line 449, in handle_exception
    self.raise_uncaught_exception(exc)
  File "/media/ubuntu/OSDisk/Users/jason.c.brown/Desktop/git/env/local/lib/python2.7/site-packages/rest_framework/views.py", line 486, in dispatch
    response = handler(request, *args, **kwargs)
  File "/media/ubuntu/OSDisk/Users/jason.c.brown/Desktop/git/env/local/lib/python2.7/site-packages/rest_framework/decorators.py", line 52, in handler
    return func(*args, **kwargs)
  File "/media/ubuntu/OSDisk/Users/jason.c.brown/Desktop/git/netops-api/ops/views.py", line 45, in cmds_list
    return Response(serializer.data)
  File "/media/ubuntu/OSDisk/Users/jason.c.brown/Desktop/git/env/local/lib/python2.7/site-packages/rest_framework/serializers.py", line 534, in data
    ret = super(Serializer, self).data
  File "/media/ubuntu/OSDisk/Users/jason.c.brown/Desktop/git/env/local/lib/python2.7/site-packages/rest_framework/serializers.py", line 263, in data
    self._data = self.to_representation(self.instance)
  File "/media/ubuntu/OSDisk/Users/jason.c.brown/Desktop/git/env/local/lib/python2.7/site-packages/rest_framework/serializers.py", line 501, in to_representation
    ret[field.field_name] = field.to_representation(attribute)
  File "/media/ubuntu/OSDisk/Users/jason.c.brown/Desktop/git/env/local/lib/python2.7/site-packages/rest_framework/fields.py", line 913, in to_representation
    return int(value)
TypeError: int() argument must be a string or a number, not 'DeferredAttribute'
[10/Aug/2017 00:37:29] "GET /ops/cmd/ HTTP/1.1" 500 117954
Performing system checks...

System check identified no issues (0 silenced).
August 10, 2017 - 00:34:18
Django version 1.11.3, using settings 'api.settings'
Starting development server at http://127.0.0.1:8000/
Quit the server with CONTROL-C.
Performing system checks...

System check identified no issues (0 silenced).
August 10, 2017 - 00:37:37
Django version 1.11.3, using settings 'api.settings'
Starting development server at http://127.0.0.1:8000/
Quit the server with CONTROL-C.
Unhandled exception in thread started by <function wrapper at 0x7f23c1dae050>
Performing system checks...

Traceback (most recent call last):
  File "/media/ubuntu/OSDisk/Users/jason.c.brown/Desktop/git/env/local/lib/python2.7/site-packages/django/utils/autoreload.py", line 227, in wrapper
    fn(*args, **kwargs)
  File "/media/ubuntu/OSDisk/Users/jason.c.brown/Desktop/git/env/local/lib/python2.7/site-packages/django/core/management/commands/runserver.py", line 125, in inner_run
    self.check(display_num_errors=True)
  File "/media/ubuntu/OSDisk/Users/jason.c.brown/Desktop/git/env/local/lib/python2.7/site-packages/django/core/management/base.py", line 359, in check
    include_deployment_checks=include_deployment_checks,
  File "/media/ubuntu/OSDisk/Users/jason.c.brown/Desktop/git/env/local/lib/python2.7/site-packages/django/core/management/base.py", line 346, in _run_checks
    return checks.run_checks(**kwargs)
  File "/media/ubuntu/OSDisk/Users/jason.c.brown/Desktop/git/env/local/lib/python2.7/site-packages/django/core/checks/registry.py", line 81, in run_checks
    new_errors = check(app_configs=app_configs)
  File "/media/ubuntu/OSDisk/Users/jason.c.brown/Desktop/git/env/local/lib/python2.7/site-packages/django/core/checks/urls.py", line 16, in check_url_config
    return check_resolver(resolver)
  File "/media/ubuntu/OSDisk/Users/jason.c.brown/Desktop/git/env/local/lib/python2.7/site-packages/django/core/checks/urls.py", line 26, in check_resolver
    return check_method()
  File "/media/ubuntu/OSDisk/Users/jason.c.brown/Desktop/git/env/local/lib/python2.7/site-packages/django/urls/resolvers.py", line 254, in check
    for pattern in self.url_patterns:
  File "/media/ubuntu/OSDisk/Users/jason.c.brown/Desktop/git/env/local/lib/python2.7/site-packages/django/utils/functional.py", line 35, in __get__
    res = instance.__dict__[self.name] = self.func(instance)
  File "/media/ubuntu/OSDisk/Users/jason.c.brown/Desktop/git/env/local/lib/python2.7/site-packages/django/urls/resolvers.py", line 405, in url_patterns
    patterns = getattr(self.urlconf_module, "urlpatterns", self.urlconf_module)
  File "/media/ubuntu/OSDisk/Users/jason.c.brown/Desktop/git/env/local/lib/python2.7/site-packages/django/utils/functional.py", line 35, in __get__
    res = instance.__dict__[self.name] = self.func(instance)
  File "/media/ubuntu/OSDisk/Users/jason.c.brown/Desktop/git/env/local/lib/python2.7/site-packages/django/urls/resolvers.py", line 398, in urlconf_module
    return import_module(self.urlconf_name)
  File "/usr/lib/python2.7/importlib/__init__.py", line 37, in import_module
    __import__(name)
  File "/media/ubuntu/OSDisk/Users/jason.c.brown/Desktop/git/netops-api/api/urls.py", line 19, in <module>
    from ops import views
  File "/media/ubuntu/OSDisk/Users/jason.c.brown/Desktop/git/netops-api/ops/views.py", line 44
    serializer = CmdSerializer(Cmds) , many=True)
                                                ^
SyntaxError: invalid syntax
Unhandled exception in thread started by <function wrapper at 0x7fa01b35a050>
Performing system checks...

Traceback (most recent call last):
  File "/media/ubuntu/OSDisk/Users/jason.c.brown/Desktop/git/env/local/lib/python2.7/site-packages/django/utils/autoreload.py", line 227, in wrapper
    fn(*args, **kwargs)
  File "/media/ubuntu/OSDisk/Users/jason.c.brown/Desktop/git/env/local/lib/python2.7/site-packages/django/core/management/commands/runserver.py", line 125, in inner_run
    self.check(display_num_errors=True)
  File "/media/ubuntu/OSDisk/Users/jason.c.brown/Desktop/git/env/local/lib/python2.7/site-packages/django/core/management/base.py", line 359, in check
    include_deployment_checks=include_deployment_checks,
  File "/media/ubuntu/OSDisk/Users/jason.c.brown/Desktop/git/env/local/lib/python2.7/site-packages/django/core/management/base.py", line 346, in _run_checks
    return checks.run_checks(**kwargs)
  File "/media/ubuntu/OSDisk/Users/jason.c.brown/Desktop/git/env/local/lib/python2.7/site-packages/django/core/checks/registry.py", line 81, in run_checks
    new_errors = check(app_configs=app_configs)
  File "/media/ubuntu/OSDisk/Users/jason.c.brown/Desktop/git/env/local/lib/python2.7/site-packages/django/core/checks/urls.py", line 16, in check_url_config
    return check_resolver(resolver)
  File "/media/ubuntu/OSDisk/Users/jason.c.brown/Desktop/git/env/local/lib/python2.7/site-packages/django/core/checks/urls.py", line 26, in check_resolver
    return check_method()
  File "/media/ubuntu/OSDisk/Users/jason.c.brown/Desktop/git/env/local/lib/python2.7/site-packages/django/urls/resolvers.py", line 254, in check
    for pattern in self.url_patterns:
  File "/media/ubuntu/OSDisk/Users/jason.c.brown/Desktop/git/env/local/lib/python2.7/site-packages/django/utils/functional.py", line 35, in __get__
    res = instance.__dict__[self.name] = self.func(instance)
  File "/media/ubuntu/OSDisk/Users/jason.c.brown/Desktop/git/env/local/lib/python2.7/site-packages/django/urls/resolvers.py", line 405, in url_patterns
    patterns = getattr(self.urlconf_module, "urlpatterns", self.urlconf_module)
  File "/media/ubuntu/OSDisk/Users/jason.c.brown/Desktop/git/env/local/lib/python2.7/site-packages/django/utils/functional.py", line 35, in __get__
    res = instance.__dict__[self.name] = self.func(instance)
  File "/media/ubuntu/OSDisk/Users/jason.c.brown/Desktop/git/env/local/lib/python2.7/site-packages/django/urls/resolvers.py", line 398, in urlconf_module
    return import_module(self.urlconf_name)
  File "/usr/lib/python2.7/importlib/__init__.py", line 37, in import_module
    __import__(name)
  File "/media/ubuntu/OSDisk/Users/jason.c.brown/Desktop/git/netops-api/api/urls.py", line 19, in <module>
    from ops import views
  File "/media/ubuntu/OSDisk/Users/jason.c.brown/Desktop/git/netops-api/ops/views.py", line 44
    serializer = CmdSerializer(Cmds), many=True)
                                               ^
SyntaxError: invalid syntax
Unhandled exception in thread started by <function wrapper at 0x7f80f43ab050>
Performing system checks...

Traceback (most recent call last):
  File "/media/ubuntu/OSDisk/Users/jason.c.brown/Desktop/git/env/local/lib/python2.7/site-packages/django/utils/autoreload.py", line 227, in wrapper
    fn(*args, **kwargs)
  File "/media/ubuntu/OSDisk/Users/jason.c.brown/Desktop/git/env/local/lib/python2.7/site-packages/django/core/management/commands/runserver.py", line 125, in inner_run
    self.check(display_num_errors=True)
  File "/media/ubuntu/OSDisk/Users/jason.c.brown/Desktop/git/env/local/lib/python2.7/site-packages/django/core/management/base.py", line 359, in check
    include_deployment_checks=include_deployment_checks,
  File "/media/ubuntu/OSDisk/Users/jason.c.brown/Desktop/git/env/local/lib/python2.7/site-packages/django/core/management/base.py", line 346, in _run_checks
    return checks.run_checks(**kwargs)
  File "/media/ubuntu/OSDisk/Users/jason.c.brown/Desktop/git/env/local/lib/python2.7/site-packages/django/core/checks/registry.py", line 81, in run_checks
    new_errors = check(app_configs=app_configs)
  File "/media/ubuntu/OSDisk/Users/jason.c.brown/Desktop/git/env/local/lib/python2.7/site-packages/django/core/checks/urls.py", line 16, in check_url_config
    return check_resolver(resolver)
  File "/media/ubuntu/OSDisk/Users/jason.c.brown/Desktop/git/env/local/lib/python2.7/site-packages/django/core/checks/urls.py", line 26, in check_resolver
    return check_method()
  File "/media/ubuntu/OSDisk/Users/jason.c.brown/Desktop/git/env/local/lib/python2.7/site-packages/django/urls/resolvers.py", line 254, in check
    for pattern in self.url_patterns:
  File "/media/ubuntu/OSDisk/Users/jason.c.brown/Desktop/git/env/local/lib/python2.7/site-packages/django/utils/functional.py", line 35, in __get__
    res = instance.__dict__[self.name] = self.func(instance)
  File "/media/ubuntu/OSDisk/Users/jason.c.brown/Desktop/git/env/local/lib/python2.7/site-packages/django/urls/resolvers.py", line 405, in url_patterns
    patterns = getattr(self.urlconf_module, "urlpatterns", self.urlconf_module)
  File "/media/ubuntu/OSDisk/Users/jason.c.brown/Desktop/git/env/local/lib/python2.7/site-packages/django/utils/functional.py", line 35, in __get__
    res = instance.__dict__[self.name] = self.func(instance)
  File "/media/ubuntu/OSDisk/Users/jason.c.brown/Desktop/git/env/local/lib/python2.7/site-packages/django/urls/resolvers.py", line 398, in urlconf_module
    return import_module(self.urlconf_name)
  File "/usr/lib/python2.7/importlib/__init__.py", line 37, in import_module
    __import__(name)
  File "/media/ubuntu/OSDisk/Users/jason.c.brown/Desktop/git/netops-api/api/urls.py", line 19, in <module>
    from ops import views
  File "/media/ubuntu/OSDisk/Users/jason.c.brown/Desktop/git/netops-api/ops/views.py", line 44
    serializer = CmdSerializer(Cmds)) #, many=True)
                                    ^
SyntaxError: invalid syntax
Traceback (most recent call last):
  File "manage.py", line 17, in <module>
    "Couldn't import Django. Are you sure it's installed and "
ImportError: Couldn't import Django. Are you sure it's installed and available on your PYTHONPATH environment variable? Did you forget to activate a virtual environment?
Error: That port is already in use.
[10/Aug/2017 17:49:13] "GET /ops/cmd HTTP/1.1" 301 0
[10/Aug/2017 17:49:13] "GET /ops/cmd/ HTTP/1.1" 403 4750
[10/Aug/2017 17:49:14] "GET /static/rest_framework/css/bootstrap.min.css HTTP/1.1" 200 121200
[10/Aug/2017 17:49:14] "GET /static/rest_framework/css/default.css HTTP/1.1" 200 1132
[10/Aug/2017 17:49:14] "GET /static/rest_framework/css/bootstrap-tweaks.css HTTP/1.1" 200 3385
[10/Aug/2017 17:49:14] "GET /static/rest_framework/css/prettify.css HTTP/1.1" 200 817
[10/Aug/2017 17:49:14] "GET /static/rest_framework/js/jquery-1.12.4.min.js HTTP/1.1" 200 97163
[10/Aug/2017 17:49:14] "GET /static/rest_framework/js/ajax-form.js HTTP/1.1" 200 2876
[10/Aug/2017 17:49:14] "GET /static/rest_framework/js/csrf.js HTTP/1.1" 200 1735
[10/Aug/2017 17:49:14] "GET /static/rest_framework/js/prettify-min.js HTTP/1.1" 200 13632
[10/Aug/2017 17:49:14] "GET /static/rest_framework/js/bootstrap.min.js HTTP/1.1" 200 37045
[10/Aug/2017 17:49:14] "GET /static/rest_framework/js/default.js HTTP/1.1" 200 1262
[10/Aug/2017 17:49:14] "GET /static/rest_framework/img/grid.png HTTP/1.1" 200 1458
Not Found: /favicon.ico
[10/Aug/2017 17:49:14] "GET /favicon.ico HTTP/1.1" 404 4151
Not Found: /favicon.ico
[10/Aug/2017 17:49:14] "GET /favicon.ico HTTP/1.1" 404 4151
[10/Aug/2017 17:49:17] "GET /api-auth/login/?next=/ops/cmd/ HTTP/1.1" 200 2702
[10/Aug/2017 17:49:23] "POST /api-auth/login/ HTTP/1.1" 302 0
[10/Aug/2017 17:49:23] "GET /ops/cmd/ HTTP/1.1" 200 7094
[10/Aug/2017 17:49:55] "POST /ops/cmd/ HTTP/1.1" 400 4855
[10/Aug/2017 17:50:11] "GET /ops/cmd/ HTTP/1.1" 200 7094
[10/Aug/2017 17:50:25] "POST /ops/cmd/ HTTP/1.1" 400 4855
[10/Aug/2017 17:50:48] "GET / HTTP/1.1" 200 5320
Performing system checks...

System check identified no issues (0 silenced).
August 10, 2017 - 17:49:04
Django version 1.11.3, using settings 'api.settings'
Starting development server at http://127.0.0.1:8000/
Quit the server with CONTROL-C.
Performing system checks...

System check identified no issues (0 silenced).
August 10, 2017 - 17:57:07
Django version 1.11.3, using settings 'api.settings'
Starting development server at http://127.0.0.1:8000/
Quit the server with CONTROL-C.
Unhandled exception in thread started by <function wrapper at 0x7fefb550e050>
Performing system checks...

Traceback (most recent call last):
  File "/media/ubuntu/OSDisk/Users/jason.c.brown/Desktop/git/env/local/lib/python2.7/site-packages/django/utils/autoreload.py", line 227, in wrapper
    fn(*args, **kwargs)
  File "/media/ubuntu/OSDisk/Users/jason.c.brown/Desktop/git/env/local/lib/python2.7/site-packages/django/core/management/commands/runserver.py", line 125, in inner_run
    self.check(display_num_errors=True)
  File "/media/ubuntu/OSDisk/Users/jason.c.brown/Desktop/git/env/local/lib/python2.7/site-packages/django/core/management/base.py", line 359, in check
    include_deployment_checks=include_deployment_checks,
  File "/media/ubuntu/OSDisk/Users/jason.c.brown/Desktop/git/env/local/lib/python2.7/site-packages/django/core/management/base.py", line 346, in _run_checks
    return checks.run_checks(**kwargs)
  File "/media/ubuntu/OSDisk/Users/jason.c.brown/Desktop/git/env/local/lib/python2.7/site-packages/django/core/checks/registry.py", line 81, in run_checks
    new_errors = check(app_configs=app_configs)
  File "/media/ubuntu/OSDisk/Users/jason.c.brown/Desktop/git/env/local/lib/python2.7/site-packages/django/core/checks/urls.py", line 16, in check_url_config
    return check_resolver(resolver)
  File "/media/ubuntu/OSDisk/Users/jason.c.brown/Desktop/git/env/local/lib/python2.7/site-packages/django/core/checks/urls.py", line 26, in check_resolver
    return check_method()
  File "/media/ubuntu/OSDisk/Users/jason.c.brown/Desktop/git/env/local/lib/python2.7/site-packages/django/urls/resolvers.py", line 254, in check
    for pattern in self.url_patterns:
  File "/media/ubuntu/OSDisk/Users/jason.c.brown/Desktop/git/env/local/lib/python2.7/site-packages/django/utils/functional.py", line 35, in __get__
    res = instance.__dict__[self.name] = self.func(instance)
  File "/media/ubuntu/OSDisk/Users/jason.c.brown/Desktop/git/env/local/lib/python2.7/site-packages/django/urls/resolvers.py", line 405, in url_patterns
    patterns = getattr(self.urlconf_module, "urlpatterns", self.urlconf_module)
  File "/media/ubuntu/OSDisk/Users/jason.c.brown/Desktop/git/env/local/lib/python2.7/site-packages/django/utils/functional.py", line 35, in __get__
    res = instance.__dict__[self.name] = self.func(instance)
  File "/media/ubuntu/OSDisk/Users/jason.c.brown/Desktop/git/env/local/lib/python2.7/site-packages/django/urls/resolvers.py", line 398, in urlconf_module
    return import_module(self.urlconf_name)
  File "/usr/lib/python2.7/importlib/__init__.py", line 37, in import_module
    __import__(name)
  File "/media/ubuntu/OSDisk/Users/jason.c.brown/Desktop/git/netops-api/api/urls.py", line 24, in <module>
    router.register(r'commands', views.CmdViewSet)
AttributeError: 'module' object has no attribute 'CmdViewSet'
[10/Aug/2017 17:58:18] "GET / HTTP/1.1" 200 5452
[10/Aug/2017 17:58:18] "GET /static/rest_framework/css/default.css HTTP/1.1" 304 0
[10/Aug/2017 17:58:18] "GET /static/rest_framework/css/bootstrap.min.css HTTP/1.1" 304 0
[10/Aug/2017 17:58:18] "GET /static/rest_framework/css/bootstrap-tweaks.css HTTP/1.1" 304 0
[10/Aug/2017 17:58:18] "GET /static/rest_framework/js/jquery-1.12.4.min.js HTTP/1.1" 304 0
[10/Aug/2017 17:58:18] "GET /static/rest_framework/js/ajax-form.js HTTP/1.1" 304 0
[10/Aug/2017 17:58:18] "GET /static/rest_framework/js/csrf.js HTTP/1.1" 304 0
[10/Aug/2017 17:58:18] "GET /static/rest_framework/js/prettify-min.js HTTP/1.1" 304 0
[10/Aug/2017 17:58:18] "GET /static/rest_framework/css/prettify.css HTTP/1.1" 304 0
[10/Aug/2017 17:58:18] "GET /static/rest_framework/js/bootstrap.min.js HTTP/1.1" 304 0
[10/Aug/2017 17:58:18] "GET /static/rest_framework/js/default.js HTTP/1.1" 304 0
[10/Aug/2017 17:58:18] "GET /static/rest_framework/img/grid.png HTTP/1.1" 304 0
/media/ubuntu/OSDisk/Users/jason.c.brown/Desktop/git/env/local/lib/python2.7/site-packages/rest_framework/pagination.py:208: UnorderedObjectListWarning: Pagination may yield inconsistent results with an unordered object_list: <class 'ops.models.Cmds'> QuerySet.
  paginator = self.django_paginator_class(queryset, page_size)
[10/Aug/2017 17:58:21] "GET /commands/ HTTP/1.1" 200 10626
[10/Aug/2017 17:58:30] "GET /commands/ HTTP/1.1" 200 10626
[10/Aug/2017 17:58:34] "GET /commands/ HTTP/1.1" 200 10626
[10/Aug/2017 17:58:38] "GET /commands/1 HTTP/1.1" 301 0
Not Found: /commands/1/
[10/Aug/2017 17:58:38] "GET /commands/1/ HTTP/1.1" 404 11567
Not Found: /commands/1/
[10/Aug/2017 17:59:00] "PUT /commands/1/ HTTP/1.1" 404 11567
[10/Aug/2017 17:59:07] "GET /commands/2/ HTTP/1.1" 200 11888
Not Found: /commands/1/
[10/Aug/2017 18:00:05] "GET /commands/1/ HTTP/1.1" 404 11567
Not Found: /commands/1/
[10/Aug/2017 18:00:46] "PUT /commands/1/ HTTP/1.1" 404 11567
Not Found: /commands/1/
[10/Aug/2017 18:01:02] "PATCH /commands/1/ HTTP/1.1" 404 11569
[10/Aug/2017 18:01:15] "GET /commands/ HTTP/1.1" 200 10626
[10/Aug/2017 18:01:44] "POST /commands/ HTTP/1.1" 201 10493
[10/Aug/2017 18:02:47] "GET /commands/3 HTTP/1.1" 301 0
[10/Aug/2017 18:02:48] "GET /commands/3/ HTTP/1.1" 200 11898
[10/Aug/2017 18:02:54] "DELETE /commands/3/ HTTP/1.1" 200 11521
[10/Aug/2017 18:03:01] "GET /commands/ HTTP/1.1" 200 10626
[10/Aug/2017 18:03:11] "GET /commands/ HTTP/1.1" 200 10626
[10/Aug/2017 18:03:39] "POST /commands/ HTTP/1.1" 201 10491
[10/Aug/2017 18:03:44] "GET /commands/ HTTP/1.1" 200 10936
[10/Aug/2017 18:04:05] "OPTIONS /commands/ HTTP/1.1" 200 14296
[10/Aug/2017 18:04:20] "GET /commands/ HTTP/1.1" 200 10936
[10/Aug/2017 18:04:35] "GET / HTTP/1.1" 200 5452
[10/Aug/2017 18:04:38] "GET /users/ HTTP/1.1" 200 10156
Performing system checks...

System check identified no issues (0 silenced).
August 10, 2017 - 17:58:17
Django version 1.11.3, using settings 'api.settings'
Starting development server at http://127.0.0.1:8000/
Quit the server with CONTROL-C.
[10/Aug/2017 18:08:42] "GET / HTTP/1.1" 200 5452
/media/ubuntu/OSDisk/Users/jason.c.brown/Desktop/git/env/local/lib/python2.7/site-packages/rest_framework/pagination.py:208: UnorderedObjectListWarning: Pagination may yield inconsistent results with an unordered object_list: <class 'ops.models.Cmds'> QuerySet.
  paginator = self.django_paginator_class(queryset, page_size)
[10/Aug/2017 18:08:45] "GET /commands/ HTTP/1.1" 200 10936
[10/Aug/2017 18:13:36] "GET / HTTP/1.1" 200 5452
[10/Aug/2017 18:13:42] "GET /commands/ HTTP/1.1" 200 10936
[10/Aug/2017 18:14:45] "POST /commands/ HTTP/1.1" 201 10516
[10/Aug/2017 18:14:50] "GET /commands/ HTTP/1.1" 200 11259
[10/Aug/2017 18:14:58] "GET /commands/5 HTTP/1.1" 301 0
[10/Aug/2017 18:14:58] "GET /commands/5/ HTTP/1.1" 200 11933
[10/Aug/2017 18:15:04] "PUT /commands/5/ HTTP/1.1" 200 11925
[10/Aug/2017 18:15:19] "GET /commands/ HTTP/1.1" 200 11256
[10/Aug/2017 18:15:20] "GET / HTTP/1.1" 200 5452
/media/ubuntu/OSDisk/Users/jason.c.brown/Desktop/git/env/local/lib/python2.7/site-packages/rest_framework/pagination.py:208: UnorderedObjectListWarning: Pagination may yield inconsistent results with an unordered object_list: <class 'django.contrib.auth.models.Group'> QuerySet.
  paginator = self.django_paginator_class(queryset, page_size)
[10/Aug/2017 18:15:23] "GET /groups/ HTTP/1.1" 200 8749
[10/Aug/2017 18:15:25] "GET /groups/1/ HTTP/1.1" 200 9991
[10/Aug/2017 18:15:30] "GET / HTTP/1.1" 200 5452
[10/Aug/2017 18:15:32] "GET /commands/ HTTP/1.1" 200 11256
[10/Aug/2017 18:16:14] "GET /commands/5/ HTTP/1.1" 200 11925
[10/Aug/2017 18:16:25] "GET / HTTP/1.1" 200 5452
[10/Aug/2017 18:16:27] "GET /users/ HTTP/1.1" 200 10156
[10/Aug/2017 18:16:29] "GET /users/2/ HTTP/1.1" 200 11137
[10/Aug/2017 18:16:54] "GET / HTTP/1.1" 200 5452
[10/Aug/2017 18:17:49] "GET /commands/ HTTP/1.1" 200 11256
Performing system checks...

System check identified no issues (0 silenced).
August 10, 2017 - 18:08:34
Django version 1.11.3, using settings 'api.settings'
Starting development server at http://127.0.0.1:8000/
Quit the server with CONTROL-C.
/media/ubuntu/OSDisk/Users/jason.c.brown/Desktop/git/env/local/lib/python2.7/site-packages/rest_framework/pagination.py:208: UnorderedObjectListWarning: Pagination may yield inconsistent results with an unordered object_list: <class 'ops.models.Cmds'> QuerySet.
  paginator = self.django_paginator_class(queryset, page_size)
[10/Aug/2017 18:18:39] "GET /commands/ HTTP/1.1" 200 11418
[10/Aug/2017 18:18:39] "GET /static/rest_framework/css/bootstrap-tweaks.css HTTP/1.1" 304 0
[10/Aug/2017 18:18:39] "GET /static/rest_framework/css/prettify.css HTTP/1.1" 304 0
[10/Aug/2017 18:18:39] "GET /static/rest_framework/css/default.css HTTP/1.1" 304 0
[10/Aug/2017 18:18:39] "GET /static/rest_framework/css/bootstrap.min.css HTTP/1.1" 304 0
[10/Aug/2017 18:18:39] "GET /static/rest_framework/js/csrf.js HTTP/1.1" 304 0
[10/Aug/2017 18:18:39] "GET /static/rest_framework/js/ajax-form.js HTTP/1.1" 304 0
[10/Aug/2017 18:18:39] "GET /static/rest_framework/js/prettify-min.js HTTP/1.1" 304 0
[10/Aug/2017 18:18:39] "GET /static/rest_framework/js/bootstrap.min.js HTTP/1.1" 304 0
[10/Aug/2017 18:18:39] "GET /static/rest_framework/js/default.js HTTP/1.1" 304 0
[10/Aug/2017 18:18:39] "GET /static/rest_framework/js/jquery-1.12.4.min.js HTTP/1.1" 304 0
[10/Aug/2017 18:18:39] "GET /static/rest_framework/img/grid.png HTTP/1.1" 304 0
Performing system checks...

System check identified no issues (0 silenced).
August 10, 2017 - 18:18:37
Django version 1.11.3, using settings 'api.settings'
Starting development server at http://127.0.0.1:8000/
Quit the server with CONTROL-C.
/media/ubuntu/OSDisk/Users/jason.c.brown/Desktop/git/env/local/lib/python2.7/site-packages/rest_framework/pagination.py:208: UnorderedObjectListWarning: Pagination may yield inconsistent results with an unordered object_list: <class 'ops.models.Cmds'> QuerySet.
  paginator = self.django_paginator_class(queryset, page_size)
[10/Aug/2017 18:28:51] "GET /commands/ HTTP/1.1" 200 11418
[10/Aug/2017 18:28:54] "GET /commands/ HTTP/1.1" 200 11418
[10/Aug/2017 18:28:55] "GET /commands/ HTTP/1.1" 200 11418
[10/Aug/2017 18:28:55] "GET /static/rest_framework/css/bootstrap.min.css HTTP/1.1" 304 0
[10/Aug/2017 18:28:55] "GET /static/rest_framework/css/default.css HTTP/1.1" 304 0
[10/Aug/2017 18:28:55] "GET /static/rest_framework/js/jquery-1.12.4.min.js HTTP/1.1" 304 0
[10/Aug/2017 18:28:55] "GET /static/rest_framework/css/bootstrap-tweaks.css HTTP/1.1" 304 0
[10/Aug/2017 18:28:55] "GET /static/rest_framework/css/prettify.css HTTP/1.1" 304 0
[10/Aug/2017 18:28:55] "GET /static/rest_framework/js/ajax-form.js HTTP/1.1" 304 0
[10/Aug/2017 18:28:55] "GET /static/rest_framework/js/csrf.js HTTP/1.1" 304 0
[10/Aug/2017 18:28:55] "GET /static/rest_framework/js/bootstrap.min.js HTTP/1.1" 304 0
[10/Aug/2017 18:28:55] "GET /static/rest_framework/js/prettify-min.js HTTP/1.1" 304 0
[10/Aug/2017 18:28:55] "GET /static/rest_framework/js/default.js HTTP/1.1" 304 0
[10/Aug/2017 18:28:56] "GET /static/rest_framework/img/grid.png HTTP/1.1" 304 0
Performing system checks...

System check identified no issues (0 silenced).
August 10, 2017 - 18:24:10
Django version 1.11.3, using settings 'api.settings'
Starting development server at http://127.0.0.1:8000/
Quit the server with CONTROL-C.
Performing system checks...

System check identified no issues (0 silenced).
August 10, 2017 - 18:44:35
Django version 1.11.3, using settings 'api.settings'
Starting development server at http://127.0.0.1:8000/
Quit the server with CONTROL-C.
[10/Aug/2017 18:45:56] "GET /commands/ HTTP/1.1" 200 11580
Performing system checks...

System check identified no issues (0 silenced).
August 10, 2017 - 18:45:55
Django version 1.11.3, using settings 'api.settings'
Starting development server at http://127.0.0.1:8000/
Quit the server with CONTROL-C.
